Workbook

Sheet Table-View
A1: 1. View Name - | B1: IMPACT_OUTSTANDING_ACTIVITY_FACT_V | F1: Please read review comments on Table Functional Description, Data Type and Business Definition
A2: 2. Table Name (From DA Team) - | B2: IMP_OTSND_AVY_FACT
A3: 3. View Schema Name - | B3: SSDS_DAL_OWNER
A4: 4. Table Schema Name - | B4: TRANSACTIONS_OWNER
A5: 5. Table Functional Description /Comment in Oracle/Redshift - | B5: This table contains taxlot recods which are closed and whose impact is already considered as realized gain/loss. | F5: BA Responsbility | G5: BA Responsbility | H5: BA Responsbility | I5: DA Responsibility
A6: 6. Filter Criteria - | B6: None
A7: 7. Grain - Please see Grain Columns sheet.
A8: Lighthouse Target | S8: Source | Z8: Transformation
A9: Logical Name of Attribute (Name of column in View without underscores) | B9: DA Comments to BA | C9: Physical Name of Attribute (Name of column in Table) Supplied by DA Team | D9: Data type in Oracle VARCHAR2(n), DATE, NUMBER(m,n), TIMETSTAMP(6) | E9: Nullable in Table and in Oracle View NULL, NOT NULL | F9: Data type in Redshift | G9: Nullable in View in Redshift | H9: Business Definition (To go into comments and into Meta Data Hub) | I9: Sample data values | J9: Action on Attribute Add,Update,Remove, Blank | K9: Comments on when it was added / updated. List the PBI or Bug number. | L9: Include in View. Populated with N only when not to be shown in the view. | M9: Is on Data Model DA responsibility | N9: Model Data Type match TRUE/FALSE DA Responsibilty | Q9: On Table | U9: On view | V9: Source Schema | W9: Source Table | X9: Source Attribute Name | Y9: Data Type | Z9: Nullable? | AA9: Transformation /Business Rules /Join Conditions | AB9: Notes / Comments
A10: IMPACT Outstanding Activity ID | C10: IMP_OTSND_AVY_FACT_ID | D10: NUMBER(38,0) | E10: No | F10: NUMERIC(38,0) | G10: No | H10: Sequencial Unique Identifier | M10: =VLOOKUP(A10,Model!C$2:K$281,2,FALSE)=C10 -> #N/A | N10: =VLOOKUP(A10,Model!C$2:L$137,5,FALSE)=D10 -> #N/A | Q10: =VLOOKUP(C10,Table!A$2:F$105,1,FALSE)=C10 -> #N/A | U10: =VLOOKUP(UPPER(SUBSTITUTE(A10," ","_")),View!A$2:J$158,1,FALSE) -> #N/A | V10: CCAL_REPL_OWNER | W10: IMP_OTSND_AVY | X10: IMP_OTSND_AVY_ID | Y10: NUMBER(38,0)
A11: Receive Deliver Type Code | C11: RCV_DLV_TP_CD | D11: VARCHAR2(4) | E11: Yes | F11: character varying(4) | G11: Yes | H11: Specifies the kind of transaction done by the trade. Values:P - Purchases S - Sales SRP- Opens of repurchases BRP- Closes of repurchases BRV- Opens of reverse repurchasesSRV- Closes of reverse repurchases BBC- Opens of borrows for cashSBC- Closes of borrows for cash BBP- Opens of borrows for pledge SBP- Closes of borrows for pledgeSLC- Opens of loans for cash BLC- Closes of loans for cash SLP- Opens of loans for pledgeBLP- Closes of loans for pledge BPI- Opens of pledge in SPI- Closes of pledge inSPO- Opens of pledge outBPO- Closes of pledge out SP - Partial pair-off (delivers exceed receives)BP - Partial pair-off (receives exceed delivers)BP - Full pair-offs (receives equal delivers)SM - Depository movement sell BM - Depository movement buy SDP- Opens of dollar roll repurchases BDP- Closes of dollar roll repurchases BDV- Opens of dollar roll reverse repurchasesSDV- Closes of dollar roll reverse repurchases STP- Opens of tri-party repurchases BTP- Closes of tri-party repurchasesBTV- Opens of tri-party reverse repurchases STV- Closes of tri-party reverse repurchases STO- Opens of tri-party pledges out BTO- Closes of tri-party pledges outBTI- Opens of tri-party pledges in STI- Closes of tri-party pledges in BMO- Opens of money out SMO- Closes of money outSMI- Opens of money in BMI- Closes of money in BIO- Opens of intra-firm loan outSIO- Closes of intra-firm loan out SII- Opens of intra-firm loan in BII- Closes of intra-firm loan inBDO- Opens of depository loan outSDO- Closes of depository loan out SDI- Opens of depository loan in BDI- Closes of depository loan inBFO- Opens of federal funds loan outSFO- Closes of federal funds loan out SFI- Opens of federal funds loan in BFI- Closes of federal funds loan inFP - Fail of purchases FS - Fail of salesFSRP - Fail of opens of repurchasesFBRP - Fail of closes of repurchases FBRV - Fail of opens of reverse repurchases FSRV - Fail of closes of reverse repurchasesFBBC - Fail of opens of borrows for cash FSBC - Fail of closes of borrows for cashFBBP - Fail of opens of borrows for pledge FSBP - Fail of closes of borrows for pledge FSLC - Fail of opens of loans for cashFBLC - Fail of closes of loans for cash FSLP - Fail of opens of loans for pledge FBLP - Fail of closes of loans for pledgeFBPI - Fail of opens of pledge in FSPI - Fail of closes of pledge in FSPO - Fail of opens of pledge out FBPO - Fail of closes of pledge outFSP- Fail of partial pairoff (delivers exceed receives) FBP- Fail of partial pairoff (receives exceed delivers) FSM- Fail of depository movement sell FBM- Fail of depository movement buyFSDP - Fail of opens of dollar roll repurchasesFBDP - Fail of closes of dollar roll repurchases FBDV - Fail of opens of dollar roll reverse repurchases FSDV - Fail of closes of dollar roll reverse repurchasesFSTP - Fail of opens of tri-party repurchases FBTP - Fail of closes of tri-party repurchases FBTV - Fail of opens of tri-party reverse repurchasesFSTV - Fail of closes of tri-party reverse repurchases FSTO - Fail of opens of tri-party pledges out FBTO - Fail of closes of tri-party pledges out FBTI - Fail of opens of tri-party pledges inFSTI - Fail of closes of tri-party pledges in FBMO - Fail of opens of money out FSMO - Fail of closes of money out FSMI - Fail of opens of money inFBMI - Fail of closes of money in FBIO - Fail of opens of intra-firm loan out FSIO - Fail of closes of intra-firm loan outFSII - Fail of opens of intra-firm loan in FBII - Fail of closes of intra-firm loan in FBDO - Fail of opens of depository loan out FSDO - Fail of closes of depository loan outFSDI - Fail of opens of depository loan in FBDI - Fail of closes of depository loan in FBFO - Fail of opens of federal funds loan out FSFO - Fail of closes of federal funds loan outFSFI - Fail of opens of federal funds loan in FBFI - Fail of closes of federal funds loan inSD - Consolidated Deliver Seg MovementSR - Consolidated Receive Seg MovementXP - FX Purchase Transaction.XS - FX Sale Transaction. SMB- Opens of Margin Cash BorrowsBMB- Closes of Margin Cash Borrows SSB- Opens of Secured Cash Borrows BSB- Closes of Secured Cash Borrows BML- Opens of Margin Cash Loans SML- Closes of Margin Cash Loans BSL- Opens of Secured Cash Loans SSL- Closes of Secured Cash LoansFSMB - Fail of opens of Margin Cash Borrows FBMB - Fail of closes of Margin Cash BorrowsFSSB - Fail of opens of Secured Cash BorrowsFBSB - Fail of closes of Secured Cash Borrows FBML - Fail of opens of Margin Cash LoansFSML - Fail of closes of Margin Cash Loans FBSL - Fail of opens of Secured Cash Loans FSSL - Fail of closes of Secured Cash Loans | M11: =VLOOKUP(A11,Model!C$2:K$281,2,FALSE)=C11 -> #N/A | N11: =VLOOKUP(A11,Model!C$2:L$137,5,FALSE)=D11 -> #N/A | Q11: =VLOOKUP(C11,Table!A$2:F$105,1,FALSE)=C11 -> #N/A | U11: =VLOOKUP(UPPER(SUBSTITUTE(A11," ","_")),View!A$2:J$158,1,FALSE) -> #N/A | V11: CCAL_REPL_OWNER | W11: IMP_OTSND_AVY | X11: RCV_DLV_TP_CODE | Y11: VARCHAR2(4 BYTE) | Z11: Yes
A12: Accrued Interest Amount | C12: ACR_INT_AMT | D12: NUMBER(38,6) | E12: Yes | F12: NUMERIC(38,6) | G12: Yes | H12: The interest that has accrued from the last interest payment date to the Settlement Date and that is part of the total monies involved in a transaction or a position. | M12: =VLOOKUP(A12,Model!C$2:K$281,2,FALSE)=C12 -> #N/A | N12: =VLOOKUP(A12,Model!C$2:L$137,5,FALSE)=D12 -> #N/A | Q12: =VLOOKUP(C12,Table!A$2:F$105,1,FALSE)=C12 -> #N/A | U12: =VLOOKUP(UPPER(SUBSTITUTE(A12," ","_")),View!A$2:J$158,1,FALSE) -> #N/A | V12: CCAL_REPL_OWNER | W12: IMP_OTSND_AVY | X12: ACR_INT_AMT | Y12: NUMBER(38,6) | Z12: Yes
A13: Arbitrage Number | C13: ARB_NUM | D13: NUMBER(10,0) | E13: Yes | F13: NUMERIC(10,0) | G13: Yes | H13: A number that uniquely identifies a sub profit center of a particular trader. Arbitrage numbers are assigned by the traders. | M13: =VLOOKUP(A13,Model!C$2:K$281,2,FALSE)=C13 -> #N/A | N13: =VLOOKUP(A13,Model!C$2:L$137,5,FALSE)=D13 -> #N/A | Q13: =VLOOKUP(C13,Table!A$2:F$105,1,FALSE)=C13 -> #N/A | U13: =VLOOKUP(UPPER(SUBSTITUTE(A13," ","_")),View!A$2:J$158,1,FALSE) -> #N/A | V13: CCAL_REPL_OWNER | W13: IMP_OTSND_AVY | X13: ARB_NUM | Y13: NUMBER(10,0) | Z13: Yes
A14: Customer Account number | C14: CST_AC_NUM | D14: VARCHAR2(12) | E14: Yes | F14: character varying(12) | G14: Yes | H14: A unique account number used to identify a customer account, as entered into the system. | M14: =VLOOKUP(A14,Model!C$2:K$281,2,FALSE)=C14 -> #N/A | N14: =VLOOKUP(A14,Model!C$2:L$137,5,FALSE)=D14 -> #N/A | Q14: =VLOOKUP(C14,Table!A$2:F$105,1,FALSE)=C14 -> #N/A | U14: =VLOOKUP(UPPER(SUBSTITUTE(A14," ","_")),View!A$2:J$158,1,FALSE) -> #N/A | V14: CCAL_REPL_OWNER | W14: IMP_OTSND_AVY | X14: CST_AC_NUM | Y14: VARCHAR2(12 BYTE) | Z14: Yes
A15: Transaction Price Amount | C15: TXN_PRC_AMT | D15: NUMBER(22,6) | E15: Yes | F15: NUMERIC(22,6) | G15: Yes | H15: The original transaction price in calculable form in the dominant price format of the security. | M15: =VLOOKUP(A15,Model!C$2:K$281,2,FALSE)=C15 -> #N/A | N15: =VLOOKUP(A15,Model!C$2:L$137,5,FALSE)=D15 -> #N/A | Q15: =VLOOKUP(C15,Table!A$2:F$105,1,FALSE)=C15 -> #N/A | U15: =VLOOKUP(UPPER(SUBSTITUTE(A15," ","_")),View!A$2:J$158,1,FALSE) -> #N/A | V15: CCAL_REPL_OWNER | W15: IMP_OTSND_AVY | X15: TXN_PRC | Y15: NUMBER(22,6) | Z15: Yes
A16: Group Customer Account Number | C16: GRP_CST_AC_NUM | D16: VARCHAR2(12) | E16: Yes | F16: character varying(12) | G16: Yes | H16: This field will contain a unique account number used to identify a customer group account, as entered into the system. | M16: =VLOOKUP(A16,Model!C$2:K$281,2,FALSE)=C16 -> #N/A | N16: =VLOOKUP(A16,Model!C$2:L$137,5,FALSE)=D16 -> #N/A | O16: =VLOOKUP(A16,Model!C$2:K$281,8,FALSE) -> #N/A | Q16: =VLOOKUP(C16,Table!A$2:F$105,1,FALSE)=C16 -> #N/A | U16: =VLOOKUP(UPPER(SUBSTITUTE(A16," ","_")),View!A$2:J$158,1,FALSE) -> #N/A | V16: CCAL_REPL_OWNER | W16: IMP_OTSND_AVY | X16: GRP_CST_AC_NUM | Y16: VARCHAR2(12 BYTE) | Z16: Yes
A17: Group Customer Name | C17: GRP_CST_NM | D17: VARCHAR2(30) | E17: No | F17: character varying(30) | G17: No | H17: This field will contain the name given to a customer group account, as entered into the system. | M17: =VLOOKUP(A17,Model!C$2:K$281,2,FALSE)=C17 -> #N/A | N17: =VLOOKUP(A17,Model!C$2:L$137,5,FALSE)=D17 -> #N/A | Q17: =VLOOKUP(C17,Table!A$2:F$105,1,FALSE)=C17 -> #N/A | U17: =VLOOKUP(UPPER(SUBSTITUTE(A17," ","_")),View!A$2:J$158,1,FALSE) -> #N/A | V17: CCAL_REPL_OWNER | W17: IMP_OTSND_AVY | X17: GRP_CST_NM | Y17: VARCHAR2(30 BYTE) | Z17: Yes
A18: Security Coupon Strike Price Amount | C18: SCR_CPN_STRK_PRC_AMT | D18: NUMBER(22,6) | E18: Yes | F18: NUMERIC(22,6) | G18: Yes | H18: A subfield of Key Security I.D. that is part of the key under which an instrument will be stored in the files. | M18: =VLOOKUP(A18,Model!C$2:K$281,2,FALSE)=C18 -> #N/A | N18: =VLOOKUP(A18,Model!C$2:L$137,5,FALSE)=D18 -> #N/A | Q18: =VLOOKUP(C18,Table!A$2:F$105,1,FALSE)=C18 -> #N/A | U18: =VLOOKUP(UPPER(SUBSTITUTE(A18," ","_")),View!A$2:J$158,1,FALSE) -> #N/A | V18: CCAL_REPL_OWNER | W18: IMP_OTSND_AVY | X18: SCR_CPN_STRK_PRC_AMT | Y18: NUMBER(22,6) | Z18: Yes
A19: Security Primary Commodity Code | C19: SCR_PRIM_CMDTY_CD | D19: VARCHAR2(4) | E19: Yes | F19: character varying(4) | G19: Yes | H19: A subfield of the Key Security I.D. used to designate the sort order of the Instrument. | M19: =VLOOKUP(A19,Model!C$2:K$281,2,FALSE)=C19 -> #N/A | N19: =VLOOKUP(A19,Model!C$2:L$137,5,FALSE)=D19 -> #N/A | Q19: =VLOOKUP(C19,Table!A$2:F$105,1,FALSE)=C19 -> #N/A | U19: =VLOOKUP(UPPER(SUBSTITUTE(A19," ","_")),View!A$2:J$158,1,FALSE) -> #N/A | V19: CCAL_REPL_OWNER | W19: IMP_OTSND_AVY | X19: SCR_PRIM_CMDTY_CODE | Y19: VARCHAR2(4 BYTE) | Z19: Yes
A20: Maturity Date | C20: MAT_DT | D20: DATE | E20: Yes | F20: Timestamp without time zone | G20: Yes | H20: A subfield Key Security ID that is part ofthe key under which an instrument will be stored in the files. It is divided into subfields in the following manner: Years, (Century, Year), Months and Days. | M20: =VLOOKUP(A20,Model!C$2:K$281,2,FALSE)=C20 -> #N/A | N20: =VLOOKUP(A20,Model!C$2:L$137,5,FALSE)=D20 -> #N/A | Q20: =VLOOKUP(C20,Table!A$2:F$105,1,FALSE)=C20 -> #N/A | U20: =VLOOKUP(UPPER(SUBSTITUTE(A20," ","_")),View!A$2:J$158,1,FALSE) -> #N/A | V20: CCAL_REPL_OWNER | W20: IMP_OTSND_AVY | X20: MAT_DT | Y20: DATE | Z20: Yes
A21: Market Code | C21: MKT_CD | D21: NUMBER(3,0) | E21: Yes | F21: NUMERIC(3,0) | G21: Yes | H21: A subfield of Key Security ID that is part of the key under which an instrument will be stored in the files. | M21: =VLOOKUP(A21,Model!C$2:K$281,2,FALSE)=C21 -> #N/A | N21: =VLOOKUP(A21,Model!C$2:L$137,5,FALSE)=D21 -> #N/A | Q21: =VLOOKUP(C21,Table!A$2:F$105,1,FALSE)=C21 -> #N/A | U21: =VLOOKUP(UPPER(SUBSTITUTE(A21," ","_")),View!A$2:J$158,1,FALSE) -> #N/A | V21: CCAL_REPL_OWNER | W21: IMP_OTSND_AVY | X21: MKT_CODE | Y21: NUMBER(3,0) | Z21: Yes
A22: Pool Number | C22: POOL_NUM | D22: VARCHAR2(7) | E22: No | F22: character varying(7) | G22: No | H22: A subfield of the Key Security I.D. used to designate the sort order of the instrument. | M22: =VLOOKUP(A22,Model!C$2:K$281,2,FALSE)=C22 -> #N/A | N22: =VLOOKUP(A22,Model!C$2:L$137,5,FALSE)=D22 -> #N/A | Q22: =VLOOKUP(C22,Table!A$2:F$105,1,FALSE)=C22 -> #N/A | U22: =VLOOKUP(UPPER(SUBSTITUTE(A22," ","_")),View!A$2:J$158,1,FALSE) -> #N/A | V22: CCAL_REPL_OWNER | W22: IMP_OTSND_AVY | X22: POOL_NUM | Y22: VARCHAR2(7 BYTE) | Z22: Yes
A23: Instrument Type Code | C23: IMT_TP_CD | D23: VARCHAR2(3) | E23: Yes | F23: character varying(3) | G23: Yes | H23: A subfield of Key Security I.D. that is part of the key under which an instrument will be sorted in the files. | M23: =VLOOKUP(A23,Model!C$2:K$281,2,FALSE)=C23 -> #N/A | N23: =VLOOKUP(A23,Model!C$2:L$137,5,FALSE)=D23 -> #N/A | Q23: =VLOOKUP(C23,Table!A$2:F$105,1,FALSE)=C23 -> #N/A | U23: =VLOOKUP(UPPER(SUBSTITUTE(A23," ","_")),View!A$2:J$158,1,FALSE) -> #N/A | V23: CCAL_REPL_OWNER | W23: IMP_OTSND_AVY | X23: IMT_TP_CODE | Y23: VARCHAR2(3 BYTE) | Z23: Yes
A24: Principal Amount | C24: PNP_AMT | D24: NUMBER(22,6) | E24: Yes | F24: NUMERIC(22,6) | G24: Yes | H24: The principal dollars involved in a transaction or a position. It is calculated in accordance with the principal calculations defined in the Processing Guidelines section of the Functional Specifications for the system. | M24: =VLOOKUP(A24,Model!C$2:K$281,2,FALSE)=C24 -> #N/A | N24: =VLOOKUP(A24,Model!C$2:L$137,5,FALSE)=D24 -> #N/A | Q24: =VLOOKUP(C24,Table!A$2:F$105,1,FALSE)=C24 -> #N/A | U24: =VLOOKUP(UPPER(SUBSTITUTE(A24," ","_")),View!A$2:J$158,1,FALSE) -> #N/A | V24: CCAL_REPL_OWNER | W24: IMP_OTSND_AVY | X24: PNP_AMT | Y24: NUMBER(22,6) | Z24: Yes
A25: Settlement Date | C25: SD | D25: DATE | E25: Yes | F25: Timestamp without time zone | G25: Yes | H25: The date on which a trade is to settle. | M25: =VLOOKUP(A25,Model!C$2:K$281,2,FALSE)=C25 -> #N/A | N25: =VLOOKUP(A25,Model!C$2:L$137,5,FALSE)=D25 -> #N/A | Q25: =VLOOKUP(C25,Table!A$2:F$105,1,FALSE)=C25 -> #N/A | U25: =VLOOKUP(UPPER(SUBSTITUTE(A25," ","_")),View!A$2:J$158,1,FALSE) -> #N/A | V25: CCAL_REPL_OWNER | W25: IMP_OTSND_AVY | X25: SD | Y25: DATE | Z25: Yes
A26: Return Date | C26: RET_DT | D26: DATE | E26: Yes | F26: Timestamp without time zone | G26: Yes | H26: This is the date on which the a financing agreement is to end. | M26: =VLOOKUP(A26,Model!C$2:K$281,2,FALSE)=C26 -> #N/A | N26: =VLOOKUP(A26,Model!C$2:L$137,5,FALSE)=D26 -> #N/A | Q26: =VLOOKUP(C26,Table!A$2:F$105,1,FALSE)=C26 -> #N/A | U26: =VLOOKUP(UPPER(SUBSTITUTE(A26," ","_")),View!A$2:J$158,1,FALSE) -> #N/A | V26: CCAL_REPL_OWNER | W26: IMP_OTSND_AVY | X26: RET_DT | Y26: DATE | Z26: Yes
A27: Trader Id | C27: TRDR_ID | D27: VARCHAR2(4) | E27: Yes | F27: character varying(4) | G27: Yes | H27: A field containing an alphanumeric entry that identifies a trader to the system. AAA | M27: =VLOOKUP(A27,Model!C$2:K$281,2,FALSE)=C27 -> #N/A | N27: =VLOOKUP(A27,Model!C$2:L$137,5,FALSE)=D27 -> #N/A | Q27: =VLOOKUP(C27,Table!A$2:F$105,1,FALSE)=C27 -> #N/A | U27: =VLOOKUP(UPPER(SUBSTITUTE(A27," ","_")),View!A$2:J$158,1,FALSE) -> #N/A | V27: CCAL_REPL_OWNER | W27: IMP_OTSND_AVY | X27: TRDR_ID | Y27: VARCHAR2(4 BYTE) | Z27: Yes
A28: Transaction Date | C28: TXN_DT | D28: DATE | E28: Yes | F28: Timestamp without time zone | G28: Yes | H28: A date in internal format that is the date onwhich a transaction was done. | M28: =VLOOKUP(A28,Model!C$2:K$281,2,FALSE)=C28 -> #N/A | N28: =VLOOKUP(A28,Model!C$2:L$137,5,FALSE)=D28 -> #N/A | Q28: =VLOOKUP(C28,Table!A$2:F$105,1,FALSE)=C28 -> #N/A | U28: =VLOOKUP(UPPER(SUBSTITUTE(A28," ","_")),View!A$2:J$158,1,FALSE) -> #N/A | V28: CCAL_REPL_OWNER | W28: IMP_OTSND_AVY | X28: TXN_DT | Y28: DATE | Z28: Yes
... A100: Activity Link Number | C100: AVY_LINK_NUM | D100: VARCHAR2(15) | E100: Yes | F100: character varying(15) | G100: Yes | H100: This field will contain a number used to link all pieces of a multi-collateral financing transaction and will be thedate and number of the first financing transaction entry.For Prime Broker movement records (SM/BM) this field will have the reference to the parent trade. | M100: =VLOOKUP(A100,Model!C$2:K$281,2,FALSE)=C100 -> #N/A | N100: =VLOOKUP(A100,Model!C$2:L$137,5,FALSE)=D100 -> #N/A | Q100: =VLOOKUP(C100,Table!A$2:F$105,1,FALSE)=C100 -> #N/A | U100: =VLOOKUP(UPPER(SUBSTITUTE(A100," ","_")),View!A$2:J$158,1,FALSE) -> #N/A | V100: CCAL_REPL_OWNER | W100: IMP_OTSND_AVY | X100: AVY_NUM_LINK | Y100: VARCHAR2(15 BYTE) | Z100: Yes
A101: Financing Broker Charge Amount | C101: FNC_BKR_CHRG_AMT | D101: NUMBER(11,4) | E101: Yes | F101: NUMERIC(11,4) | G101: Yes | H101: This field will contain the daily charge on financing done through a broker, this can be either a rate or a flat fee. | J101: Add | K101: PBI 1672159 | M101: =VLOOKUP(A101,Model!C$2:K$281,2,FALSE)=C101 -> #N/A | N101: =VLOOKUP(A101,Model!C$2:L$137,5,FALSE)=D101 -> #N/A | Q101: =VLOOKUP(C101,Table!A$2:F$105,1,FALSE)=C101 -> #N/A | U101: =VLOOKUP(UPPER(SUBSTITUTE(A101," ","_")),View!A$2:J$158,1,FALSE) -> #N/A | V101: CCAL_REPL_OWNER | W101: IMP_OTSND_AVY | X101: FNC_BKR_CHRG_AMT | Y101: NUMBER(11,4) | Z101: Yes
A102: Transaction Fee Amount | C102: TXN_FEE_AMT | D102: NUMBER(22,6) | E102: Yes | F102: NUMERIC(22,6) | G102: Yes | H102: The field will contain a fee to be charged on a trade. Apositive value will be charged to the customer and a negative value will be charged to the trader. | J102: Add | K102: PBI 1672159 | M102: =VLOOKUP(A102,Model!C$2:K$281,2,FALSE)=C102 -> #N/A | N102: =VLOOKUP(A102,Model!C$2:L$137,5,FALSE)=D102 -> #N/A | Q102: =VLOOKUP(C102,Table!A$2:F$105,1,FALSE)=C102 -> #N/A | U102: =VLOOKUP(UPPER(SUBSTITUTE(A102," ","_")),View!A$2:J$158,1,FALSE) -> #N/A | V102: CCAL_REPL_OWNER | W102: IMP_OTSND_AVY | X102: TXN_FEE_AMT | Y102: NUMBER(22,6) | Z102: Yes
A103: Rate Effective Date | C103: RATE_EFF_DT | D103: DATE | E103: Yes | F103: Timestamp without time zone | G103: Yes | H103: In the Historical Pool Factor File, the date on which a poolfactor for an instrument is to become effective.For financing transactions, the date on which the current rate,return date, and/or collateral changes took effect. | J103: Add | K103: PBI 1672159 | M103: =VLOOKUP(A103,Model!C$2:K$281,2,FALSE)=C103 -> #N/A | N103: =VLOOKUP(A103,Model!C$2:L$137,5,FALSE)=D103 -> #N/A | Q103: =VLOOKUP(C103,Table!A$2:F$105,1,FALSE)=C103 -> #N/A | U103: =VLOOKUP(UPPER(SUBSTITUTE(A103," ","_")),View!A$2:J$158,1,FALSE) -> #N/A | V103: CCAL_REPL_OWNER | W103: IMP_OTSND_AVY | X103: RATE_EFF_DT | Y103: DATE | Z103: Yes
A104: Firm Commission Amount | C104: FIRM_CMSN_AMT | D104: NUMBER(22,6) | E104: Yes | F104: NUMERIC(22,6) | G104: Yes | H104: This field will contain the calculabe firm commission in dollar amount. | J104: Add | K104: PBI 1672159 | M104: =VLOOKUP(A104,Model!C$2:K$281,2,FALSE)=C104 -> #N/A | N104: =VLOOKUP(A104,Model!C$2:L$137,5,FALSE)=D104 -> #N/A | Q104: =VLOOKUP(C104,Table!A$2:F$105,1,FALSE)=C104 -> #N/A | U104: =VLOOKUP(UPPER(SUBSTITUTE(A104," ","_")),View!A$2:J$158,1,FALSE) -> #N/A | V104: CCAL_REPL_OWNER | W104: IMP_OTSND_AVY | X104: FIRM_CMSN_AMT | Y104: NUMBER(22,6) | Z104: Yes
A105: Pending Accrued Interest To Date Amount | C105: PNDG_ACR_INT_TO_DT_AMT | D105: NUMBER(22,6) | E105: Yes | F105: NUMERIC(22,6) | G105: Yes | H105: The accrued interest to date up to the next business day, for transaction from the First of the month. | J105: Add | K105: PBI 1672159 | M105: =VLOOKUP(A105,Model!C$2:K$281,2,FALSE)=C105 -> #N/A | N105: =VLOOKUP(A105,Model!C$2:L$137,5,FALSE)=D105 -> #N/A | Q105: =VLOOKUP(C105,Table!A$2:F$105,1,FALSE)=C105 -> #N/A | U105: =VLOOKUP(UPPER(SUBSTITUTE(A105," ","_")),View!A$2:J$158,1,FALSE) -> #N/A | V105: CCAL_REPL_OWNER | W105: IMP_OTSND_AVY | X105: PNDG_ACR_INT_TO_DT_AMT | Y105: NUMBER(22,6) | Z105: Yes
A106: Firm Money Depository Account | C106: FIRM_MNY_DEPST_AC | D106: VARCHAR2(6) | E106: Yes | F106: character varying(6) | G106: Yes | H106: This field will indicate the depository account through which the firm's monies will settle. | J106: Add | K106: PBI 1672159 | M106: =VLOOKUP(A106,Model!C$2:K$281,2,FALSE)=C106 -> #N/A | N106: =VLOOKUP(A106,Model!C$2:L$137,5,FALSE)=D106 -> #N/A | Q106: =VLOOKUP(C106,Table!A$2:F$105,1,FALSE)=C106 -> #N/A | U106: =VLOOKUP(UPPER(SUBSTITUTE(A106," ","_")),View!A$2:J$158,1,FALSE) -> #N/A | V106: CCAL_REPL_OWNER | W106: IMP_OTSND_AVY | X106: FIRM_MNY_DEPST_AC | Y106: VARCHAR2(6) | Z106: Yes
A107: Payment Mode Code | C107: PYMT_MODE_CD | D107: VARCHAR2(1) | E107: Yes | F107: character varying(1) | G107: Yes | H107: This field will contain a Payment Mode associatied with atransaction or open item. Values may include:'blank', 'V' - Delivery Versus Payment 'D' - Demand Deposit Account 'C' - Check 'W' - Wire 'S' - Savings Account | J107: Add | K107: PBI 1672159 | M107: =VLOOKUP(A107,Model!C$2:K$281,2,FALSE)=C107 -> #N/A | N107: =VLOOKUP(A107,Model!C$2:L$137,5,FALSE)=D107 -> #N/A | Q107: =VLOOKUP(C107,Table!A$2:F$105,1,FALSE)=C107 -> #N/A | U107: =VLOOKUP(UPPER(SUBSTITUTE(A107," ","_")),View!A$2:J$158,1,FALSE) -> #N/A | V107: CCAL_REPL_OWNER | W107: IMP_OTSND_AVY | X107: PYMT_MODE_CODE | Y107: VARCHAR2(1 BYTE) | Z107: Yes
A108: Dealer Broker Other Code | C108: DEALER_BKR_OTHR_CD | D108: VARCHAR2(1) | E108: Yes | F108: character varying(1) | G108: Yes | H108: Indicates whether a customer is a dealer, broker, or other. It is used by FRB Schedule B.Values are 'D','B','O'. | J108: Add | K108: PBI 1672159 | M108: =VLOOKUP(A108,Model!C$2:K$281,2,FALSE)=C108 -> #N/A | N108: =VLOOKUP(A108,Model!C$2:L$137,5,FALSE)=D108 -> #N/A | Q108: =VLOOKUP(C108,Table!A$2:F$105,1,FALSE)=C108 -> #N/A | U108: =VLOOKUP(UPPER(SUBSTITUTE(A108," ","_")),View!A$2:J$158,1,FALSE) -> #N/A | V108: CCAL_REPL_OWNER | W108: IMP_OTSND_AVY | X108: BKR_OTHR_CODE_DEALER | Y108: VARCHAR2(1 BYTE) | Z108: Yes
A109: Finance Type Code | C109: FNC_TP_CD | D109: VARCHAR2(2) | E109: Yes | F109: character varying(2) | G109: Yes | H109: This is the type of financing that has been done. Valid entries are:'BC' - Borrow for cash 'BP' - Borrow against pledges 'LC' - Loan for cash 'LP' - Loan against pledges'PI' - Incoming pledge 'PO' - Outgoing pledge 'RP' - Repurchase 'RV' - Reverse repurchase 'DP' - Dollar Price repurchase'DV' - Dollar Price reverse repurchase 'TP' - Tri-Party repurchase'TV' - Tri-Party reverse repurchase 'TI' - Tri-Party Pledge In 'TO' - Tri-Party Pledge Out'MI' - Money In'MO' - Money Out 'MB' - Margin Cash Borrow 'ML' - Margin Cash Loan 'SB' - Secured Cash Borrow 'SL' - Secured Cash Loan | J109: Add | K109: PBI#1998286 | M109: =VLOOKUP(A109,Model!C$2:K$281,2,FALSE)=C109 -> #N/A | N109: =VLOOKUP(A109,Model!C$2:L$137,5,FALSE)=D109 -> #N/A | Q109: =VLOOKUP(C109,Table!A$2:F$105,1,FALSE)=C109 -> #N/A | U109: =VLOOKUP(UPPER(SUBSTITUTE(A109," ","_")),View!A$2:J$158,1,FALSE) -> #N/A | V109: CCAL_REPL_OWNER | W109: IMP_OTSND_AVY | X109: FNC_TP_CODE | Y109: VARCHAR2(2 BYTE) | Z109: Yes
A110: Normalized Transaction Amount | C110: NORMALIZED_TXN_AMT | D110: NUMBER(22,6) | E110: Yes | F110: NUMERIC(22,6) | G110: Yes | H110: This will contain the fully normalized amount of a transaction. | J110: Add | K110: PBI#1998286 | M110: =VLOOKUP(A110,Model!C$2:K$281,2,FALSE)=C110 -> #N/A | N110: =VLOOKUP(A110,Model!C$2:L$137,5,FALSE)=D110 -> #N/A | Q110: =VLOOKUP(C110,Table!A$2:F$105,1,FALSE)=C110 -> #N/A | U110: =VLOOKUP(UPPER(SUBSTITUTE(A110," ","_")),View!A$2:J$158,1,FALSE) -> #N/A | V110: CCAL_REPL_OWNER | W110: IMP_OTSND_AVY | X110: NORMD_TXN_AMT | Y110: NUMBER(22,6) | Z110: Yes
A111: External Trade Source Code | C111: EXT_TRD_SRC_CD | D111: VARCHAR2(3) | E111: Yes | F111: character varying(3) | G111: Yes | H111: This field indicates the source of a transaction. It is used to distinguish an E-Trade from a Regular Trade. Values: GLS : The trade is originating from the GLOSS system. BBG : The trade is originating from Bloomberg. | J111: Add | K111: PBI: 1998286 | M111: =VLOOKUP(A111,Model!C$2:K$281,2,FALSE)=C111 -> #N/A | N111: =VLOOKUP(A111,Model!C$2:L$137,5,FALSE)=D111 -> #N/A | Q111: =VLOOKUP(C111,Table!A$2:F$105,1,FALSE)=C111 -> #N/A | U111: =VLOOKUP(UPPER(SUBSTITUTE(A111," ","_")),View!A$2:J$158,1,FALSE) -> #N/A | V111: CCAL_REPL_OWNER | W111: IMP_OTSND_AVY | X111: EXT_TRD_SRC_CODE | Y111: VARCHAR2(3 BYTE) | Z111: Yes
...

Sheet Grain Columns
A1: Grain Columns
A2: IMPACT Outstanding Activity ID

Sheet ETL Notes

Sheet Additional View
A1: 1. View Name -
A2: 3. View Schema Name - SSDS_DAL_OWNER
A3: 5. Table Functional Description -
A4: 6. Filter Criteria - NA
A5: Logic if necessary:

Sheet Model
A1: Entity Name | B1: Table Name | C1: Attribute Name | D1: Column Name | E1: Attribute/Column Definition | F1: Domain | G1: Column Datatype | H1: Column Null Option
C109: f

Sheet Table
A1: COLUMN_NAME | B1: DATA_TYPE | C1: NULLABLE | D1: DATA_DEFAULT | E1: COLUMN_ID | F1: COMMENTS

Sheet View
A1: COLUMN_NAME | B1: DATA_TYPE | C1: NULLABLE | D1: DATA_DEFAULT | E1: COLUMN_ID | F1: COMMENTS | G1: INSERTABLE | H1: UPDATABLE | I1: DELETABLE
