Workbook

Sheet Table-View
A1: 1. View Name | B1: Open_Tax_Lot_Non_Brokerage_Fact_V | F1: Please read review comments on Table Functional Description, Data Type and Business Definition
A2: 2. Table Name (From DA Team) - | B2: OPN_TAX_LOTS_NON_BKR_FACT
A3: 3. View Schema Name - SSDS_DAL_OWNER
A4: 4. Table Schema Name - TAXLOT_OWNER
A5: 5. Table Functional Description /Comment in Oracle/Redshift - | B5: This table contains records for taxlots non brokerage which are Open and whose impact is yet to considered as realized gain/loss. | F5: BA Responsbility | G5: BA Responsbility | H5: BA Responsbility | I5: DA Responsibility
A6: 6. Filter Criteria - Please see ETL Notes sheet.
A7: 7. Grain - Please see Grain Columns sheet.
A8: Lighthouse Target | N8: Source | X8: Transformation
A9: Logical Name of Attribute (Name of column in View without underscores) | B9: DA Comments to BA | C9: Physical Name of Attribute (Name of column in Table) Supplied by DA Team | D9: Data type in Oracle VARCHAR2(n), DATE, NUMBER(m,n), TIMETSTAMP(6) | E9: Nullable in Table and in Oracle View NULL, NOT NULL | F9: Data type in Redshift | G9: Nullable in View in Redshift | H9: Business Definition (To go into comments and into Meta Data Hub) | I9: Sample data values | J9: Action on Attribute Add,Update,Remove, Blank | K9: Comments on when it was added / updated. List the PBI or Bug number. | L9: Include in View. Populated with N only when not to be shown in the view. | M9: Is on Data Model DA responsibility | N9: Model Data Type match TRUE/FALSE DA Responsibilty | O9: model defs. Match | R9: Is On table | S9: On View | T9: Source Schema | U9: Source Table | V9: Source Attribute Name | W9: Data Type | X9: Nullable? | Y9: Transformation /Business Rules /Join Conditions | Z9: Notes / Comments
A10: Open Tax Lots Non Brokerage Fact Id | D10: NUMBER(38,0) | E10: No | F10: NUMERIC(38,0) | G10: No | H10: This is Surrogate Key for this table. Used as Primary Key as wel | M10: =VLOOKUP(A10,Model!C$2:J$93,2,FALSE)=C10 -> #N/A | O10: =VLOOKUP(A10,Model!C$2:J$93,3,FALSE)=H10 -> #N/A | P10: =VLOOKUP(A10,Model!C$2:J$93,3,FALSE) -> #N/A | Q10: =VLOOKUP(A10,Model!C$2:J$93,8,FALSE) -> #N/A | R10: =VLOOKUP(C10,Table!A$2:F$98,1,FALSE)=C10 -> #N/A | S10: =VLOOKUP(SUBSTITUTE(A10," ","_"),View!A$2:I$106,1,FALSE) -> #N/A | W10: NUMBER(38,0) | X10: No
A11: Source System Code | C11: SRC_STM_CD | D11: VARCHAR2(40) | E11: Yes | F11: Character Varying(40) | G11: Yes | H11: TAX_LOT_OPN_MSTR.SRC_STM_ID | M11: =VLOOKUP(A11,Model!C$2:J$93,2,FALSE)=C11 -> TRUE | O11: =VLOOKUP(A11,Model!C$2:J$93,3,FALSE)=H11 -> FALSE | P11: =VLOOKUP(A11,Model!C$2:J$93,3,FALSE) -> MAXIT: Hardcode ??? We need to setup a source system RJT Source: TAX_LOT_OPN_MSTR.SRC_STM_ID | Q11: =VLOOKUP(A11,Model!C$2:J$93,8,FALSE) -> 2 | R11: =VLOOKUP(C11,Table!A$2:F$98,1,FALSE)=C11 -> TRUE | S11: =VLOOKUP(SUBSTITUTE(A11," ","_"),View!A$2:I$106,1,FALSE) -> SOURCE_SYSTEM_CODE | T11: COMMON_OWNER | U11: SRC_STM_DIM | V11: SRC_STM_CD | W11: VARCHAR2(40) | X11: Yes | Y11: Use SRC_STM_ID to get code
A12: Arrangement Id | C12: AR_ID | D12: NUMBER(38,0) | E12: Yes | F12: NUMBER(38,0) | G12: Yes | H12: Arrangement Id for the account Source:TAX_LOT_OPN_MSTR.AR_ID | M12: =VLOOKUP(A12,Model!C$2:J$93,2,FALSE)=C12 -> TRUE | O12: =VLOOKUP(A12,Model!C$2:J$93,3,FALSE)=H12 -> FALSE | P12: =VLOOKUP(A12,Model!C$2:J$93,3,FALSE) -> Arrangement Id for the account MAXIT Source:TAX_LOT_DTL_OPN/CLS.AR_ID RJT Source:TAX_LOT_OPN_MSTR.AR_ID | Q12: =VLOOKUP(A12,Model!C$2:J$93,8,FALSE) -> 3 | R12: =VLOOKUP(C12,Table!A$2:F$98,1,FALSE)=C12 -> TRUE | S12: =VLOOKUP(SUBSTITUTE(A12," ","_"),View!A$2:I$106,1,FALSE) -> ARRANGEMENT_ID | T12: TAXLOT_STG_OWNER | U12: OPN_TAX_LOTS_NONBKR_TGT | V12: AR_ID | W12: NUMBER | X12: Yes
A13: CIRD Product Id | C13: CIRD_PD_ID | D13: NUMBER(38,0) | E13: Yes | F13: NUMBER(38,0) | G13: Yes | H13: RJT Source: TAX_LOT_OPN_MSTR.CCAL_PD_ID Lookup on IMT_PD_DIM using CCAL_PD_ID PD_ID from CIRD - can be used as join key if date context is supplied at query time | M13: =VLOOKUP(A13,Model!C$2:J$93,2,FALSE)=C13 -> TRUE | O13: =VLOOKUP(A13,Model!C$2:J$93,3,FALSE)=H13 -> FALSE | P13: =VLOOKUP(A13,Model!C$2:J$93,3,FALSE) -> MAXIT Source: TAX_LOT_DTL_OPN/CLS.PD_ID RJT Source: TAX_LOT_OPN_MSTR.CCAL_PD_ID Lookup on IMT_PD_DIM using CL_PD_ID PD_ID from CIRD - can be used as join key if date context is supplied at query time | Q13: =VLOOKUP(A13,Model!C$2:J$93,8,FALSE) -> 4 | R13: =VLOOKUP(C13,Table!A$2:F$98,1,FALSE)=C13 -> TRUE | S13: =VLOOKUP(SUBSTITUTE(A13," ","_"),View!A$2:I$106,1,FALSE) -> CIRD_PRODUCT_ID | T13: CCAL_REPL_OWNER | U13: CCAL_CIRD_PD_MAP | V13: CIRD_PD_ID | W13: NUMBER | X13: Yes | Y13: Look up on CCAL_CIRD_PD_MAP where CCAL_PD_ID = TAX_LOT_OPN_MSTR.CCAL_PD_ID, pick- CIRD_PD_ID AND ACTV_F = 'Y'
A14: CCAL Product Id | C14: CCAL_PD_ID | D14: NUMBER(38,0) | E14: Yes | F14: NUMBER(38,0) | G14: Yes | H14: Product Id assigned by CCAL RJT Source: TAX_LOT_OPN_MSTR.CCAL_PD_ID | M14: =VLOOKUP(A14,Model!C$2:J$93,2,FALSE)=C14 -> TRUE | O14: =VLOOKUP(A14,Model!C$2:J$93,3,FALSE)=H14 -> FALSE | P14: =VLOOKUP(A14,Model!C$2:J$93,3,FALSE) -> Product Id assigned by CCAL MAXIT Source: TAX_LOT_DTL_OPN/CLS.PD_ID RJT Source: TAX_LOT_OPN_MSTR.CCAL_PD_ID | Q14: =VLOOKUP(A14,Model!C$2:J$93,8,FALSE) -> 5 | R14: =VLOOKUP(C14,Table!A$2:F$98,1,FALSE)=C14 -> TRUE | S14: =VLOOKUP(SUBSTITUTE(A14," ","_"),View!A$2:I$106,1,FALSE) -> CCAL_PRODUCT_ID | T14: TAXLOT_STG_OWNER | U14: OPN_TAX_LOTS_NONBKR_TGT | V14: CCAL_PD_ID | W14: NUMBER | X14: Yes
A15: Accounting Type Code | C15: ACG_TP_CD | D15: VARCHAR2(1) | E15: Yes | F15: Character Varying(1) | G15: Yes | H15: RJT Source: TAX_LOT_OPN_MSTR.ACG_TP_CODE Accounting type code P=Principal I=Income | M15: =VLOOKUP(A15,Model!C$2:J$93,2,FALSE)=C15 -> TRUE | O15: =VLOOKUP(A15,Model!C$2:J$93,3,FALSE)=H15 -> FALSE | P15: =VLOOKUP(A15,Model!C$2:J$93,3,FALSE) -> MAXIT Source: TAXLOT_DTL_OPN.AC_TP RJT Source: TAX_LOT_OPN_MSTR.ACG_TP_CODE Accounting type code from SIS (e.g., 1,2,6). 1= Cash Account 2= Margin Account 3= Special lot 2019 5= Special lot 2013 6= Short margin Account | Q15: =VLOOKUP(A15,Model!C$2:J$93,8,FALSE) -> 8 | R15: =VLOOKUP(C15,Table!A$2:F$98,1,FALSE)=C15 -> TRUE | S15: =VLOOKUP(SUBSTITUTE(A15," ","_"),View!A$2:I$106,1,FALSE) -> ACCOUNTING_TYPE_CODE | T15: TAXLOT_STG_OWNER | U15: OPN_TAX_LOTS_NONBKR_TGT | V15: AC_TP_CODE | W15: VARCHAR2(1) | X15: Yes
A16: Tax Lot External Reference Key Primary | C16: TAX_LOT_EXT_REFR_KEY_PRIM | D16: VARCHAR2(50) | E16: Yes | F16: Character Varying(50) | G16: Yes | H16: Taxlot sequence unique identifier assgined when a lot is generated in the source system. | M16: =VLOOKUP(A16,Model!C$2:J$93,2,FALSE)=C16 -> TRUE | O16: =VLOOKUP(A16,Model!C$2:J$93,3,FALSE)=H16 -> FALSE | P16: =VLOOKUP(A16,Model!C$2:J$93,3,FALSE) -> MAXIT source: MAXIT_IFCE_SEQ_ID RJT Source: TAX_LOT_OPN_MSTR.TAX_LOT_EXT_REFR_KEY_PRIM | Q16: =VLOOKUP(A16,Model!C$2:J$93,8,FALSE) -> 9 | R16: =VLOOKUP(C16,Table!A$2:F$98,1,FALSE)=C16 -> TRUE | S16: =VLOOKUP(SUBSTITUTE(A16," ","_"),View!A$2:I$106,1,FALSE) -> TAX_LOT_EXTERNAL_REFERENCE_KEY_PRIMARY | T16: TAXLOT_STG_OWNER | U16: OPN_TAX_LOTS_NONBKR_TGT | V16: TAX_LOT_EXT_REFR_KEY_PRIM | W16: VARCHAR2(50) | X16: Yes
A17: Tax Lot External Reference Key Secondary | C17: TAX_LOT_EXT_REFR_KEY_SCDY | D17: VARCHAR2(40) | E17: Yes | F17: Character Varying(40) | G17: Yes | H17: Secondary Sequence identifier of the debited tax lo assigned in the source system. Its optional not always populated | M17: =VLOOKUP(A17,Model!C$2:J$93,2,FALSE)=C17 -> TRUE | O17: =VLOOKUP(A17,Model!C$2:J$93,3,FALSE)=H17 -> FALSE | P17: =VLOOKUP(A17,Model!C$2:J$93,3,FALSE) -> source:TAXLOT_DTL_OPN.MAXIT_REL_IFCE_SEQ_ID RJT Source: TAX_LOT_OPN_MSTR.TAX_LOT_EXT_REFR_KEY_SCDY | Q17: =VLOOKUP(A17,Model!C$2:J$93,8,FALSE) -> 10 | R17: =VLOOKUP(C17,Table!A$2:F$98,1,FALSE)=C17 -> TRUE | S17: =VLOOKUP(SUBSTITUTE(A17," ","_"),View!A$2:I$106,1,FALSE) -> TAX_LOT_EXTERNAL_REFERENCE_KEY_SECONDARY | T17: TAXLOT_STG_OWNER | U17: OPN_TAX_LOTS_NONBKR_TGT | V17: TAX_LOT_EXT_REFR_KEY_SCDY | W17: VARCHAR2(40) | X17: Yes
A18: Tax Lot External Reference Key Tertiary | C18: TAX_LOT_EXT_REFR_KEY_TRTY | D18: NUMBER(38,0) | E18: Yes | F18: NUMERIC(38,0) | G18: Yes | H18: Sequence number identifier of transaction debited with a DLVR or Sell. Its optional not always popualted. | M18: =VLOOKUP(A18,Model!C$2:J$93,2,FALSE)=C18 -> TRUE | O18: =VLOOKUP(A18,Model!C$2:J$93,3,FALSE)=H18 -> FALSE | P18: =VLOOKUP(A18,Model!C$2:J$93,3,FALSE) -> Source: TAXLOT_DTL_OPN.MAXIT_TXN_LOT_ID RJT Source: TAX_LOT_OPN_MSTR.TAX_LOT_EXT_REFR_KEY_TRTY | Q18: =VLOOKUP(A18,Model!C$2:J$93,8,FALSE) -> 11 | R18: =VLOOKUP(C18,Table!A$2:F$98,1,FALSE)=C18 -> TRUE | S18: =VLOOKUP(SUBSTITUTE(A18," ","_"),View!A$2:I$106,1,FALSE) -> TAX_LOT_EXTERNAL_REFERENCE_KEY_TERTIARY | T18: TAXLOT_STG_OWNER | U18: OPN_TAX_LOTS_NONBKR_TGT | V18: TAX_LOT_EXT_REFR_KEY_TRTY | W18: NUMBER(38,0) | X18: Yes
A19: Tax Lot External Reference Key Quaternary | C19: TAX_LOT_EXT_REFR_KEY_QTRNY | D19: NUMBER(38,0) | E19: Yes | F19: NUMERIC(38,0) | G19: Yes | H19: Unique system generated identifier used to identify taxlots and create associations between taxlots. | M19: =VLOOKUP(A19,Model!C$2:J$93,2,FALSE)=C19 -> TRUE | O19: =VLOOKUP(A19,Model!C$2:J$93,3,FALSE)=H19 -> FALSE | P19: =VLOOKUP(A19,Model!C$2:J$93,3,FALSE) -> SOurce: TAXLOT_DTL_OPN.REL_LOT_ID RJT Source: TAX_LOT_OPN_MSTR.TAX_LOT_EXT_REFR_KEY_QTRNY | Q19: =VLOOKUP(A19,Model!C$2:J$93,8,FALSE) -> 12 | R19: =VLOOKUP(C19,Table!A$2:F$98,1,FALSE)=C19 -> TRUE | S19: =VLOOKUP(SUBSTITUTE(A19," ","_"),View!A$2:I$106,1,FALSE) -> TAX_LOT_EXTERNAL_REFERENCE_KEY_QUATERNARY | T19: TAXLOT_STG_OWNER | U19: OPN_TAX_LOTS_NONBKR_TGT | V19: TAX_LOT_EXT_REFR_KEY_QTRNY | W19: NUMBER(38,0) | X19: Yes
A20: End Date | C20: END_DT | D20: DATE | E20: No | F20: Timestamp without time zone | G20: No | H20: Date on which row is no longer active. Specify as MyDate >= EFF_DT AND MyDate < END_DT to select a row that is active@MyDate | M20: =VLOOKUP(A20,Model!C$2:J$93,2,FALSE)=C20 -> TRUE | O20: =VLOOKUP(A20,Model!C$2:J$93,3,FALSE)=H20 -> FALSE | P20: =VLOOKUP(A20,Model!C$2:J$93,3,FALSE) -> MAXIT Source: TAXLOT_DTL_OPN.END_DT RJT Source: TAX_LOT_OPN_ASOF.EFF_TO_DT | Q20: =VLOOKUP(A20,Model!C$2:J$93,8,FALSE) -> 13 | R20: =VLOOKUP(C20,Table!A$2:F$98,1,FALSE)=C20 -> TRUE | S20: =VLOOKUP(SUBSTITUTE(A20," ","_"),View!A$2:I$106,1,FALSE) -> END_DATE | T20: TAXLOT_STG_OWNER | U20: OPN_TAX_LOTS_NONBKR_TGT | V20: EFF_TO_DT | W20: DATE | X20: No
A21: Effective Date | C21: EFF_DT | D21: DATE | E21: Yes | F21: Timestamp without time zone | G21: Yes | H21: Specify as MyDate >= EFF_DT AND MyDate < END_DT to select a row that is active@MyDate | M21: =VLOOKUP(A21,Model!C$2:J$93,2,FALSE)=C21 -> TRUE | O21: =VLOOKUP(A21,Model!C$2:J$93,3,FALSE)=H21 -> FALSE | P21: =VLOOKUP(A21,Model!C$2:J$93,3,FALSE) -> MAXIT Source: TAXLOT_DTL_OPN.EFF_DT_x000D_ RJT Source: TAX_LOT_OPN_ASOF.EFF_FM_DT_x000D_ _x000D_ | Q21: =VLOOKUP(A21,Model!C$2:J$93,8,FALSE) -> 14 | R21: =VLOOKUP(C21,Table!A$2:F$98,1,FALSE)=C21 -> TRUE | S21: =VLOOKUP(SUBSTITUTE(A21," ","_"),View!A$2:I$106,1,FALSE) -> EFFECTIVE_DATE | T21: TAXLOT_STG_OWNER | U21: OPN_TAX_LOTS_NONBKR_TGT | V21: EFF_FM_DT | W21: DATE | X21: Yes
A22: Accounting Type Name | C22: ACG_TP_NM | D22: VARCHAR2(500) | E22: Yes | F22: Character Varying(500) | G22: Yes | H22: TAX_LOT_OPN_MSTR.ACG_TP_CODE Lookup on Accounting Type Dimension Accounting type name (e.g., cash account,margin account) | M22: =VLOOKUP(A22,Model!C$2:J$93,2,FALSE)=C22 -> TRUE | O22: =VLOOKUP(A22,Model!C$2:J$93,3,FALSE)=H22 -> FALSE | P22: =VLOOKUP(A22,Model!C$2:J$93,3,FALSE) -> MAXIT Source: TAXLOT_DTL_OPN.AC_TP RJT Source: TAX_LOT_OPN_MSTR.ACG_TP_CODE Lookup on Accounting Type Dimension Accounting type name (e.g., cash account,margin account) | Q22: =VLOOKUP(A22,Model!C$2:J$93,8,FALSE) -> 16 | R22: =VLOOKUP(C22,Table!A$2:F$98,1,FALSE)=C22 -> TRUE | S22: =VLOOKUP(SUBSTITUTE(A22," ","_"),View!A$2:I$106,1,FALSE) -> ACCOUNTING_TYPE_NAME | T22: COMMON_OWNER | U22: ACG_TP_DIM | V22: ACG_TP_NM | W22: VARCHAR2(500) | X22: Yes | Y22: Lookup on Accounting Type Dimension Use TAX_LOT_OPN_MSTR.ACG_TP_CODE to get ACG_TP_NM
A23: Acquired Date | C23: ACQ_DT | D23: DATE | E23: Yes | F23: Timestamp without time zone | G23: Yes | H23: Always the buy/opening lot opening date. When there is a sell, the buy date against which the sell happened will be populated. If there are multiple buys against a sell, the sell is broken down into multiple taxlots. Note: This is sometime referred to as opening trade date. | M23: =VLOOKUP(A23,Model!C$2:J$93,2,FALSE)=C23 -> TRUE | O23: =VLOOKUP(A23,Model!C$2:J$93,3,FALSE)=H23 -> FALSE | P23: =VLOOKUP(A23,Model!C$2:J$93,3,FALSE) -> Date on which the lot was acquired_x000D_ MAXIT source: TAXLOT_DTL_OPN.ACQ_DT_x000D_ RJT Source:TAX_LOT_OPN_MSTR.TD_x000D_ _x000D_ | Q23: =VLOOKUP(A23,Model!C$2:J$93,8,FALSE) -> 19 | R23: =VLOOKUP(C23,Table!A$2:F$98,1,FALSE)=C23 -> TRUE | S23: =VLOOKUP(SUBSTITUTE(A23," ","_"),View!A$2:I$106,1,FALSE) -> ACQUIRED_DATE | T23: TAXLOT_STG_OWNER | U23: OPN_TAX_LOTS_NONBKR_TGT | V23: ACQ_DT | W23: DATE | X23: Yes
A24: Adjusted Cost | C24: ADJ_COST | D24: NUMBER(22,6) | E24: Yes | F24: NUMERIC(22,6) | G24: Yes | H24: For a Buy, the tax cost is shown. For a Sell, Tax Cost sold is populated. | M24: =VLOOKUP(A24,Model!C$2:J$93,2,FALSE)=C24 -> TRUE | O24: =VLOOKUP(A24,Model!C$2:J$93,3,FALSE)=H24 -> FALSE | P24: =VLOOKUP(A24,Model!C$2:J$93,3,FALSE) -> Adjusted cost for the Lot MAXIT source: TAXLOT_DTL_OPN.ADJ_COST RJT Source: TAX_LOT_OPN_ASOF NML_CCY_ASOF_ADJ_COST_AMT | Q24: =VLOOKUP(A24,Model!C$2:J$93,8,FALSE) -> 20 | R24: =VLOOKUP(C24,Table!A$2:F$98,1,FALSE)=C24 -> TRUE | S24: =VLOOKUP(SUBSTITUTE(A24," ","_"),View!A$2:I$106,1,FALSE) -> ADJUSTED_COST | T24: TAXLOT_STG_OWNER | U24: OPN_TAX_LOTS_NONBKR_TGT | V24: SBC_ASOF_ADJ_COST_AMT | W24: NUMBER(22,6) | X24: Yes | Y24: ADJ_COST, case when (CCY_CODE ='USD' or (EXG_RATE is NULL OR EXG_RATE = 0)) THEN ADJ_COST ELSE ADJ_COST * EXG_RATE END SBC_ADJ_COST
A25: Currency Code | C25: CCY_CD | D25: VARCHAR2(7) | E25: Yes | F25: Character Varying(7) | G25: Yes | H25: ISO certified3 alpha codes. | M25: =VLOOKUP(A25,Model!C$2:J$93,2,FALSE)=C25 -> TRUE | O25: =VLOOKUP(A25,Model!C$2:J$93,3,FALSE)=H25 -> FALSE | P25: =VLOOKUP(A25,Model!C$2:J$93,3,FALSE) -> MAXIT Source: TAXLOT_DTL_OPN.CCY_CODE RJT Source: TAX_LOT_OPN_ASOF.NML_ISO_CCY_CODE | Q25: =VLOOKUP(A25,Model!C$2:J$93,8,FALSE) -> 23 | R25: =VLOOKUP(C25,Table!A$2:F$98,1,FALSE)=C25 -> TRUE | S25: =VLOOKUP(SUBSTITUTE(A25," ","_"),View!A$2:I$106,1,FALSE) -> CURRENCY_CODE | T25: TAXLOT_STG_OWNER | U25: OPN_TAX_LOTS_NONBKR_TGT | V25: STM_BASE_ISO_CCY_CODE | W25: VARCHAR2(7) | X25: Yes
A26: Certificate Number | C26: CTF_NUM | D26: VARCHAR2(40) | E26: Yes | F26: Character Varying(40) | G26: Yes | H26: Certificate Number Provided by CBRS. | M26: =VLOOKUP(A26,Model!C$2:J$93,2,FALSE)=C26 -> TRUE | O26: =VLOOKUP(A26,Model!C$2:J$93,3,FALSE)=H26 -> FALSE | P26: =VLOOKUP(A26,Model!C$2:J$93,3,FALSE) -> MAXIT Source:TAXLOT_DTL_OPN.CTF_NUM RJT Source: TAX_LOT_OPN_MSTR.TAX_LOT_CTF_NUM | Q26: =VLOOKUP(A26,Model!C$2:J$93,8,FALSE) -> 24 | R26: =VLOOKUP(C26,Table!A$2:F$98,1,FALSE)=C26 -> TRUE | S26: =VLOOKUP(SUBSTITUTE(A26," ","_"),View!A$2:I$106,1,FALSE) -> CERTIFICATE_NUMBER | T26: TAXLOT_STG_OWNER | U26: OPN_TAX_LOTS_NONBKR_TGT | V26: TAX_LOT_CTF_NUM | W26: VARCHAR2(40) | X26: Yes
A27: Certificate Number Prefix | C27: CTF_NUM_PFX | D27: VARCHAR2(40) | E27: Yes | F27: Character Varying(40) | G27: Yes | H27: Certificate Number Prefix Provided by CBRS. | M27: =VLOOKUP(A27,Model!C$2:J$93,2,FALSE)=C27 -> TRUE | O27: =VLOOKUP(A27,Model!C$2:J$93,3,FALSE)=H27 -> FALSE | P27: =VLOOKUP(A27,Model!C$2:J$93,3,FALSE) -> MAXIT Source:TAXLOT_DTL_OPN.CTF_NUM_PFX RJT Source: TAX_LOT_OPN_MSTR.TAX_LOT_CTF_NUM_PFX | Q27: =VLOOKUP(A27,Model!C$2:J$93,8,FALSE) -> 25 | R27: =VLOOKUP(C27,Table!A$2:F$98,1,FALSE)=C27 -> TRUE | S27: =VLOOKUP(SUBSTITUTE(A27," ","_"),View!A$2:I$106,1,FALSE) -> CERTIFICATE_NUMBER_PREFIX | T27: TAXLOT_STG_OWNER | U27: OPN_TAX_LOTS_NONBKR_TGT | V27: TAX_LOT_CTF_NUM_PFX | W27: VARCHAR2(40) | X27: Yes
A28: Cost Basis Legislation Coverage Code | C28: COST_BSS_LEGS_CVR_CD | D28: VARCHAR2(1) | E28: Yes | F28: Character Varying(1) | G28: Yes | H28: Cost Basis Legislation Coverage: “covered” securities are those impacted by the cost basis legislation (which is dependent on the security type and acquisition date) and subject to the new IRS reporting requirements. | M28: =VLOOKUP(A28,Model!C$2:J$93,2,FALSE)=C28 -> TRUE | O28: =VLOOKUP(A28,Model!C$2:J$93,3,FALSE)=H28 -> FALSE | P28: =VLOOKUP(A28,Model!C$2:J$93,3,FALSE) -> Cost Basis Legislation Coverage: ?covered? securities are those impacted by the cost basis legislation (which is dependent on the security type and acquisition date) and subject to the new IRS reporting requirements. U = Uncovered Tax Lot C = Covered Tax Lot MAXIT Source: TAXLOT_DTL_OPN.CVRD_UNCVRD RJT Source: TAX_LOT_OPN_MSTR.CVRD_F | Q28: =VLOOKUP(A28,Model!C$2:J$93,8,FALSE) -> 26 | R28: =VLOOKUP(C28,Table!A$2:F$98,1,FALSE)=C28 -> TRUE | S28: =VLOOKUP(SUBSTITUTE(A28," ","_"),View!A$2:I$106,1,FALSE) -> COST_BASIS_LEGISLATION_COVERAGE_CODE | T28: TAXLOT_STG_OWNER | U28: OPN_TAX_LOTS_NONBKR_TGT | V28: CVRD_UNCVRD | W28: VARCHAR2(1) | X28: Yes
A29: Disallowed Wash Sale Amount | C29: DISALWD_WASH_SALE_AMT | D29: NUMBER(22,6) | E29: Yes | F29: NUMERIC(22,6) | G29: Yes | H29: A wash sale is sale of a security at a loss and repurchase of the same or substantially identical security shortly before or after. The wash-sale rule states that the tax loss will be disallowed if you buy the same security, a contract or option to buy the security, or a "substantially identical" security, within 30 days before or after the date you sold the loss-generating investment | M29: =VLOOKUP(A29,Model!C$2:J$93,2,FALSE)=C29 -> TRUE | O29: =VLOOKUP(A29,Model!C$2:J$93,3,FALSE)=H29 -> FALSE | P29: =VLOOKUP(A29,Model!C$2:J$93,3,FALSE) -> MAXIT Source: TAXLOT_DTL_OPN.DISALWD_WASHSALE_AMT RJT Source: TAX_LOT_OPN_MSTR.NML_CCY_WASH_SALE_AMT | Q29: =VLOOKUP(A29,Model!C$2:J$93,8,FALSE) -> 27 | R29: =VLOOKUP(C29,Table!A$2:F$98,1,FALSE)=C29 -> TRUE | S29: =VLOOKUP(SUBSTITUTE(A29," ","_"),View!A$2:I$106,1,FALSE) -> DISALLOWED_WASH_SALE_AMOUNT | T29: TAXLOT_STG_OWNER | U29: OPN_TAX_LOTS_NONBKR_TGT | V29: SBC_WASH_SALE_AMT | W29: NUMBER(22,6) | X29: Yes
A30: Exchange Rate | C30: EXG_RATE | D30: NUMBER(22,6) | E30: Yes | F30: NUMERIC(22,6) | G30: Yes | H30: This is an exchange rate for foreign currency. | M30: =VLOOKUP(A30,Model!C$2:J$93,2,FALSE)=C30 -> TRUE | O30: =VLOOKUP(A30,Model!C$2:J$93,3,FALSE)=H30 -> FALSE | P30: =VLOOKUP(A30,Model!C$2:J$93,3,FALSE) -> MAXIT Source: TAXLOT_DTL_OPN.EXG_RATE RJT Source: TAX_LOT_OPN_ASOF.SBC_EXG_RATE | Q30: =VLOOKUP(A30,Model!C$2:J$93,8,FALSE) -> 28 | R30: =VLOOKUP(C30,Table!A$2:F$98,1,FALSE)=C30 -> TRUE | S30: =VLOOKUP(SUBSTITUTE(A30," ","_"),View!A$2:I$106,1,FALSE) -> EXCHANGE_RATE | T30: TAXLOT_STG_OWNER | U30: OPN_TAX_LOTS_NONBKR_TGT | V30: SBC_EXG_RATE | W30: NUMBER(22,6) | X30: Yes
A31: Fair Market Value Of Gift Or Inheritance | C31: FAIR_MKT_VAL_OF_GIFT_OR_INHTN | D31: NUMBER(22,6) | E31: Yes | F31: NUMERIC(22,6) | G31: Yes | H31: Fair market value of the tax lot at the point of gifting or inheritance For gifted or inherited trns only. | M31: =VLOOKUP(A31,Model!C$2:J$93,2,FALSE)=C31 -> TRUE | O31: =VLOOKUP(A31,Model!C$2:J$93,3,FALSE)=H31 -> FALSE | P31: =VLOOKUP(A31,Model!C$2:J$93,3,FALSE) -> MAXIT Source: TAXLOT_DTL_OPN.FMV RJT SOurce: TAX_LOT_OPN_ASOF.NML_CCY_ASOF_FAIR_MKT_VAL_AMT For MAXIT (Brokerage) Fair market value of the tax lot at the point of gifting or inheritance Source: FMV For gifted or inherited transactions only. Sourced from: 1) account to account RAD Activity receive record sent to Maxit from RJ 2) CBRS record received from contra firm 3) manual entry by business | Q31: =VLOOKUP(A31,Model!C$2:J$93,8,FALSE) -> 29 | R31: =VLOOKUP(C31,Table!A$2:F$98,1,FALSE)=C31 -> TRUE | S31: =VLOOKUP(SUBSTITUTE(A31," ","_"),View!A$2:I$106,1,FALSE) -> FAIR_MARKET_VALUE_OF_GIFT_OR_INHERITANCE | T31: TAXLOT_STG_OWNER | U31: OPN_TAX_LOTS_NONBKR_TGT | V31: SBC_ASOF_FAIR_MKT_VAL_AMT | W31: NUMBER(22,6) | X31: Yes | Y31: FMV FAIR_MKT_VAL_OF_GIFT_OR_INHTN, case when (CCY_CODE ='USD' or (EXG_RATE is NULL OR EXG_RATE = 0)) THEN FMV ELSE FMV * EXG_RATE END SBC_FAIR_MKT_VAL
A32: Gift Date | C32: GIFT_DT | D32: DATE | E32: Yes | F32: Timestamp without time zone | G32: Yes | H32: Date of death for inheritance or Date of a gifted taxlot. | M32: =VLOOKUP(A32,Model!C$2:J$93,2,FALSE)=C32 -> TRUE | O32: =VLOOKUP(A32,Model!C$2:J$93,3,FALSE)=H32 -> FALSE | P32: =VLOOKUP(A32,Model!C$2:J$93,3,FALSE) -> MAXIT Source: TAXLOT_DTL_OPN.GIFT_DT RJT Source: TAX_LOT_OPN_MSTR.GIFT_DT For gifted tax lots this gives date of gift. Source: GIFT_DT | Q32: =VLOOKUP(A32,Model!C$2:J$93,8,FALSE) -> 30 | R32: =VLOOKUP(C32,Table!A$2:F$98,1,FALSE)=C32 -> TRUE | S32: =VLOOKUP(SUBSTITUTE(A32," ","_"),View!A$2:I$106,1,FALSE) -> GIFT_DATE | T32: TAXLOT_STG_OWNER | U32: OPN_TAX_LOTS_NONBKR_TGT | V32: GIFT_DT | W32: DATE | X32: Yes
A33: Position Inception Date | C33: POS_INCPTN_DT | D33: DATE | E33: Yes | F33: Timestamp without time zone | G33: Yes | H33: Holding date of the opening tax lot. Is available on the sell transaction as well. Note: This should coincide with the acquisition date unless the sale is affected by an action in which the acquisition date changes but the holding date stays the same. i.e. wash sale, gifts, etc.) | M33: =VLOOKUP(A33,Model!C$2:J$93,2,FALSE)=C33 -> TRUE | O33: =VLOOKUP(A33,Model!C$2:J$93,3,FALSE)=H33 -> FALSE | P33: =VLOOKUP(A33,Model!C$2:J$93,3,FALSE) -> Holding date of the opening tax lot. Is available on the sell transaction as well. Note: This should coincide with the acquisition date unless the sale is affected by an action in which the acquisition date changes but the holding date stays the same. i.e. wash sale, gifts, etc.) Used to calculate the term for most cases MAXIT Source: TAXLOT_DTL_OPN.HLDG_DT RJT Source: TAX_LOT_OPN_MSTR.POS_INCPTN_DT | Q33: =VLOOKUP(A33,Model!C$2:J$93,8,FALSE) -> 31 | R33: =VLOOKUP(C33,Table!A$2:F$98,1,FALSE)=C33 -> TRUE | S33: =VLOOKUP(SUBSTITUTE(A33," ","_"),View!A$2:I$106,1,FALSE) -> POSITION_INCEPTION_DATE | T33: TAXLOT_STG_OWNER | U33: OPN_TAX_LOTS_NONBKR_TGT | V33: POS_INCPTN_DT | W33: DATE | X33: Yes
A34: Long Short Position Code | C34: LONG_SHRT_POS_CD | D34: VARCHAR2(1) | E34: Yes | F34: Character Varying(1) | G34: Yes | H34: A value that represents the tax lot being a long or short position. Valid Values: L = Long S = Short | M34: =VLOOKUP(A34,Model!C$2:J$93,2,FALSE)=C34 -> TRUE | O34: =VLOOKUP(A34,Model!C$2:J$93,3,FALSE)=H34 -> FALSE | P34: =VLOOKUP(A34,Model!C$2:J$93,3,FALSE) -> A value that represents the tax lot being a long or short position. Valid Values: L = Long S = Short MAXIT Source: TAXLOT_DTL_OPN.LONG_SHRT_POS rjt sOURCE: TAX_LOT_OPN_MSTR.POS_LONG_SHRT_CODE | Q34: =VLOOKUP(A34,Model!C$2:J$93,8,FALSE) -> 32 | R34: =VLOOKUP(C34,Table!A$2:F$98,1,FALSE)=C34 -> TRUE | S34: =VLOOKUP(SUBSTITUTE(A34," ","_"),View!A$2:I$106,1,FALSE) -> LONG_SHORT_POSITION_CODE | T34: TAXLOT_STG_OWNER | U34: OPN_TAX_LOTS_NONBKR_TGT | V34: POS_LONG_SHRT_CODE | W34: VARCHAR2(1) | X34: Yes
A35: Loss Not Allowed Flag | C35: LOSS_NOT_ALWD_F | D35: VARCHAR2(1) | E35: Yes | F35: Character Varying(1) | G35: Yes | H35: The loss on a transaction that is disallowed for tax purposes because it is part of a wash sale. | M35: =VLOOKUP(A35,Model!C$2:J$93,2,FALSE)=C35 -> TRUE | O35: =VLOOKUP(A35,Model!C$2:J$93,3,FALSE)=H35 -> FALSE | P35: =VLOOKUP(A35,Model!C$2:J$93,3,FALSE) -> MAXIT Source: TAXLOT_DTL_OPN.LOSS_NOT_ALLOWED RJT Source: None In a cash and stock merger the client may not be allowed to take a loss on the disposition of the old stock, any losses are rolled into the new stock. Merger / Acquisition or Corporate Inversion Transactions. This field is currently used on Closed Tax Lot Tax Reporting at this time. Values: N = No, Loss allowed Y = Yes, No Loss allowed | Q35: =VLOOKUP(A35,Model!C$2:J$93,8,FALSE) -> 33 | R35: =VLOOKUP(C35,Table!A$2:F$98,1,FALSE)=C35 -> TRUE | S35: =VLOOKUP(SUBSTITUTE(A35," ","_"),View!A$2:I$106,1,FALSE) -> LOSS_NOT_ALLOWED_FLAG | V35: NULL | W35: VARCHAR2(1) | X35: Yes
A36: Life To Date Market Discount | C36: LIFE_TO_DTD_MKT_DCN | D36: NUMBER(22,6) | E36: Yes | F36: NUMERIC(22,6) | G36: Yes | H36: Life-to-Date Market Discount calculated from the open date or the last adjustment date of the fixed income security | M36: =VLOOKUP(A36,Model!C$2:J$93,2,FALSE)=C36 -> TRUE | O36: =VLOOKUP(A36,Model!C$2:J$93,3,FALSE)=H36 -> FALSE | P36: =VLOOKUP(A36,Model!C$2:J$93,3,FALSE) -> Life to date market discount amount_x000D_ _x000D_ Total market discount accrued since the purchase of the bond_x000D_ _x000D_ MAXIT Source: TAXLOT_DTL_OPN.LTD_MKT_DISCOUNT | Q36: =VLOOKUP(A36,Model!C$2:J$93,8,FALSE) -> 34 | R36: =VLOOKUP(C36,Table!A$2:F$98,1,FALSE)=C36 -> TRUE | S36: =VLOOKUP(SUBSTITUTE(A36," ","_"),View!A$2:I$106,1,FALSE) -> LIFE_TO_DATE_MARKET_DISCOUNT | V36: NULL | W36: NUMBER(22,6) | X36: Yes
A37: Missing Cost Basis Flag | C37: MISS_COST_BSS_F | D37: VARCHAR2(1) | E37: Yes | F37: Character Varying(1) | G37: Yes | H37: Indicates that Cost basis is not available for this position | M37: =VLOOKUP(A37,Model!C$2:J$93,2,FALSE)=C37 -> TRUE | O37: =VLOOKUP(A37,Model!C$2:J$93,3,FALSE)=H37 -> FALSE | P37: =VLOOKUP(A37,Model!C$2:J$93,3,FALSE) -> Indicates that Cost basis is not available for this position MAXIT Source: TAXLOT_DTL_OPN.MISS_COST_F RJT Source: TAX_LOT_OPN_MSTR.MISS_COST_F | Q37: =VLOOKUP(A37,Model!C$2:J$93,8,FALSE) -> 35 | R37: =VLOOKUP(C37,Table!A$2:F$98,1,FALSE)=C37 -> TRUE | S37: =VLOOKUP(SUBSTITUTE(A37," ","_"),View!A$2:I$106,1,FALSE) -> MISSING_COST_BASIS_FLAG | T37: TAXLOT_STG_OWNER | U37: OPN_TAX_LOTS_NONBKR_TGT | V37: MISS_COST_F | W37: VARCHAR2(1) | X37: Yes | Y37: CASE WHEN (TAX_LOT_OPN_MSTR.MISS_COST_F = 'Y' OR TAX_LOT_OPN_MSTR.null_bss_f = 'Y') THEN 'Y' ELSE 'N' END
A38: Adjusted Cost Not Accurate Flag | C38: ADJ_COST_NOT_ACRT_F | D38: VARCHAR2(1) | E38: Yes | F38: Character Varying(1) | G38: Yes | H38: Indcates that Adjusted Cost is not accurate due to missing cost on atleast one sublot Source:NULL_F Y = YES – At least one of the associated average cost records is missing average cost N = NO – None of the associated average cost records are missing average cost | M38: =VLOOKUP(A38,Model!C$2:J$93,2,FALSE)=C38 -> TRUE | O38: =VLOOKUP(A38,Model!C$2:J$93,3,FALSE)=H38 -> FALSE | P38: =VLOOKUP(A38,Model!C$2:J$93,3,FALSE) -> MAXIT Source: TAXLOT_DTL_OPN.NULL_F RJT Source: TAX_LOT_OPN_MSTR.NULL_BSS_F Indcates that Adjusted Cost is not accurate due to missing cost on atleast one sublot Source:NULL_F Y = YES ? At least one of the associated average cost records is missing average cost N = NO ? None of the associated average cost records are missing average cost | Q38: =VLOOKUP(A38,Model!C$2:J$93,8,FALSE) -> 36 | R38: =VLOOKUP(C38,Table!A$2:F$98,1,FALSE)=C38 -> TRUE | S38: =VLOOKUP(SUBSTITUTE(A38," ","_"),View!A$2:I$106,1,FALSE) -> ADJUSTED_COST_NOT_ACCURATE_FLAG | T38: TAXLOT_STG_OWNER | U38: OPN_TAX_LOTS_NONBKR_TGT | V38: NULL_BSS_F | W38: VARCHAR2(1) | X38: Yes
A39: Open Price Factor | C39: OPN_PRC_FCTR | D39: NUMBER(22,6) | E39: Yes | F39: NUMERIC(22,6) | G39: Yes | H39: Price_factor of opening transaction Used for factored bonds RJT Source: TAX_LOT_OPN_MSTR.NML_CCY_OPN_PRC_FCTR | M39: =VLOOKUP(A39,Model!C$2:J$93,2,FALSE)=C39 -> TRUE | O39: =VLOOKUP(A39,Model!C$2:J$93,3,FALSE)=H39 -> FALSE | P39: =VLOOKUP(A39,Model!C$2:J$93,3,FALSE) -> Price_factor of opening transaction Used for factored bonds MAXIT Source: TAXLOT_DTL_OPN.OPN_FCTR RJT Source: TAX_LOT_OPN_MSTR.NML_CCY_OPN_PRC_FCTR | Q39: =VLOOKUP(A39,Model!C$2:J$93,8,FALSE) -> 37 | R39: =VLOOKUP(C39,Table!A$2:F$98,1,FALSE)=C39 -> TRUE | S39: =VLOOKUP(SUBSTITUTE(A39," ","_"),View!A$2:I$106,1,FALSE) -> OPEN_PRICE_FACTOR | T39: TAXLOT_STG_OWNER | U39: OPN_TAX_LOTS_NONBKR_TGT | V39: SBC_OPN_PRC_FCTR | W39: NUMBER(22,6) | X39: Yes | Y39: OPN_FCTR OPN_PRC_FCTR, case when (CCY_CODE ='USD' or (EXG_RATE is NULL OR EXG_RATE = 0)) THEN OPN_FCTR ELSE OPN_FCTR * EXG_RATE END SBC_OPN_PRC_FCTR
A40: Open Transaction Event Type | C40: OPN_TXN_EV_TP | D40: VARCHAR2(40) | E40: Yes | F40: Character Varying(40) | G40: Yes | H40: RJT Source: TAX_LOT_OPN_MSTR.TAX_LOT_TXN_EV_TP_ID For open and closed lots, this field includes the 'event' of the opening transaction | M40: =VLOOKUP(A40,Model!C$2:J$93,2,FALSE)=C40 -> TRUE | O40: =VLOOKUP(A40,Model!C$2:J$93,3,FALSE)=H40 -> FALSE | P40: =VLOOKUP(A40,Model!C$2:J$93,3,FALSE) -> Source: TAXLOT_DTL_OPN.OPN_TXN_EV_ID RJT Source: TAX_LOT_OPN_MSTR.TAX_LOT_TXN_EV_TP_ID For open lots ? Maxit Event ID For closed lots ? Maxit Event ID of the closing transaction For open and closed lots, this field includes the 'event' of the opening transaction This is a Maxit created Event Name to identify tax lots and create associations between tax lots " | Q40: =VLOOKUP(A40,Model!C$2:J$93,8,FALSE) -> 38 | R40: =VLOOKUP(C40,Table!A$2:F$98,1,FALSE)=C40 -> TRUE | S40: =VLOOKUP(SUBSTITUTE(A40," ","_"),View!A$2:I$106,1,FALSE) -> OPEN_TRANSACTION_EVENT_TYPE | T40: CCAL_REPL_OWNER | U40: CL_VAL | V40: CL_VAL_NM | W40: VARCHAR2(40) | X40: Yes | Y40: Use TAX_LOT_TXN_EV_TP_ID in CL_VAL_ID in CL_VAL table and pick CL_VAL_NM where CL_SCM_CD= 86
...

Sheet View
A1: COLUMN_NAME | B1: DATA_TYPE | C1: NULLABLE | D1: DATA_DEFAULT | E1: COLUMN_ID | F1: COMMENTS | G1: INSERTABLE | H1: UPDATABLE | I1: DELETABLE
A2: ACAT_TYPE | B2: VARCHAR2(500) | C2: Yes | E2: 15 | G2: YES | H2: YES | I2: YES
A3: ACAT_TYPE_CODE | B3: VARCHAR2(40) | C3: Yes | E3: 16 | G3: YES | H3: YES | I3: YES
A4: ACCOUNTING_TYPE_CODE | B4: VARCHAR2(1) | C4: Yes | E4: 6 | G4: YES | H4: YES | I4: YES
A5: ACCOUNTING_TYPE_DIMENSION_ID | B5: NUMBER(38) | C5: No | E5: 13 | G5: YES | H5: YES | I5: YES
A6: ACCOUNTING_TYPE_ID | B6: NUMBER(38) | C6: Yes | E6: 67 | G6: YES | H6: YES | I6: YES
A7: ACCOUNTING_TYPE_NAME | B7: VARCHAR2(500) | C7: Yes | E7: 14 | G7: YES | H7: YES | I7: YES
A8: ACQUIRED_DATE | B8: DATE | C8: Yes | E8: 17 | G8: YES | H8: YES | I8: YES
A9: ACQUIRED_DATE_DIMENSION_ID | B9: NUMBER(38) | C9: No | E9: 72 | G9: YES | H9: YES | I9: YES
A10: ADJUSTED_COST | B10: NUMBER(22,6) | C10: Yes | E10: 18 | G10: YES | H10: YES | I10: YES
A11: ADJUSTED_COST_NOT_ACCURATE_FLAG | B11: VARCHAR2(1) | C11: Yes | E11: 34 | G11: YES | H11: YES | I11: YES
A12: ARRANGEMENT_ID | B12: NUMBER | C12: Yes | E12: 3 | G12: YES | H12: YES | I12: YES
A13: BUY_TRADE_NUMBER | B13: VARCHAR2(80) | C13: Yes | E13: 20 | G13: YES | H13: YES | I13: YES
... A82: ZERO_COST_BASIS_FLAG | B82: VARCHAR2(2) | C82: Yes | E82: 54 | G82: YES | H82: YES | I82: YES

Sheet Grain Columns

Sheet ETL Notes

Sheet Additional View
A1: 1. View Name -
A2: 3. View Schema Name - SSDS_DAL_OWNER
A3: 5. Table Functional Description -
A4: 6. Filter Criteria - NA
A5: Logic if necessary:

Sheet Model
A1: Entity Name | B1: Table Name | C1: Attribute Name | D1: Column Name | E1: Attribute/Column Definition | F1: Domain | G1: Column Datatype | H1: Column Null Option
A2: Open Tax Lots Fact | B2: OPN_TAX_LOTS_FACT | C2: Acat Type | D2: ACAT_TP | E2: MAXIT Source: = TAXLOT_DTL_OPN.ACATTYPE RJT Source: None Type of Transfer indicated by the external source when transferred using ACAT Values GFT = Gift INH = Inherited ITG = Inherited Than Gifted NTT = NonTaxable to Taxable DRIP = A Direct Registration System (DRS)/Direct Reinvestment Plan NULL = none various other values are available as well | F2: Name_desc | G2: VARCHAR2(500) | H2: NULL | J2: 17
A3: Open Tax Lots Fact | B3: OPN_TAX_LOTS_FACT | C3: Acat Type Code | D3: ACAT_TP_CD | E3: MAXIT Source: = TAXLOT_DTL_OPN.ACATTYPE RJT Source: None Type of Transfer Code indicated by the external source when transferred using ACAT Values GFT = Gift INH = Inherited ITG = Inherited Than Gifted NTT = NonTaxable to Taxable DRIP = A Direct Registration System (DRS)/Direct Reinvestment Plan NULL = none various other values are available as well | F3: Code | G3: VARCHAR2(40) | H3: NULL | J3: 18
A4: Open Tax Lots Fact | B4: OPN_TAX_LOTS_FACT | C4: Accounting Type Code | D4: ACG_TP_CD | E4: MAXIT Source: TAXLOT_DTL_OPN.AC_TP RJT Source: TAX_LOT_OPN_MSTR.ACG_TP_CODE Accounting type code from SIS (e.g., 1,2,6). 1= Cash Account 2= Margin Account 3= Special lot 2019 5= Special lot 2013 6= Short margin Account | F4: Code_01 | G4: VARCHAR2(1) | H4: NULL | J4: 8
A5: Open Tax Lots Fact | B5: OPN_TAX_LOTS_FACT | C5: Accounting Type Dimension Id | D5: ACG_TP_DIM_ID | E5: MAXIT Source: TAXLOT_DTL_OPN.AC_TP RJT Source: TAX_LOT_OPN_MSTR.ACG_TP_CODE Lookup on Accounting Type Dimension | F5: NINI | G5: NUMBER(38,0) | H5: NULL | J5: 15
A6: Open Tax Lots Fact | B6: OPN_TAX_LOTS_FACT | C6: Accounting Type Id | D6: ACG_TP_ID | E6: Numeric identifier of the accounting type ID (e.g., 1006, 1001) Lookup using Accounting type Code (MAXIT TAXLOT_DTL_OPN.AC_TP, RJT TAX_LOT_OPN_MSTR.ACG_TP_CODE) | F6: NINI | G6: NUMBER(38,0) | H6: NULL | J6: 68
A7: Open Tax Lots Fact | B7: OPN_TAX_LOTS_FACT | C7: Accounting Type Name | D7: ACG_TP_NM | E7: MAXIT Source: TAXLOT_DTL_OPN.AC_TP RJT Source: TAX_LOT_OPN_MSTR.ACG_TP_CODE Lookup on Accounting Type Dimension Accounting type name (e.g., cash account,margin account) | F7: Name_desc | G7: VARCHAR2(500) | H7: NULL | J7: 16
A8: Open Tax Lots Fact | B8: OPN_TAX_LOTS_FACT | C8: Acquired Date | D8: ACQ_DT | E8: Date on which the lot was acquired_x000D_ MAXIT source: TAXLOT_DTL_OPN.ACQ_DT_x000D_ RJT Source:TAX_LOT_OPN_MSTR.TD_x000D_ _x000D_ | F8: Date | G8: DATE | H8: NULL | J8: 19
A9: Open Tax Lots Fact | B9: OPN_TAX_LOTS_FACT | C9: Acquired Date Dimension Id | D9: ACQ_DT_DIM_ID | E9: Synthetic Key identifying a single date in the DATE Dimension | F9: NINI | G9: NUMBER(38,0) | H9: NOT NULL | J9: 80
A10: Open Tax Lots Fact | B10: OPN_TAX_LOTS_FACT | C10: Adjusted Cost | D10: ADJ_COST | E10: Adjusted cost for the Lot MAXIT source: TAXLOT_DTL_OPN.ADJ_COST RJT Source: TAX_LOT_OPN_ASOF NML_CCY_ASOF_ADJ_COST_AMT | F10: a | G10: NUMBER(22,6) | H10: NULL | J10: 20
A11: Open Tax Lots Fact | B11: OPN_TAX_LOTS_FACT | C11: Adjusted cost Not Accurate Flag | D11: ADJ_COST_NOT_ACRT_F | E11: MAXIT Source: TAXLOT_DTL_OPN.NULL_F RJT Source: TAX_LOT_OPN_MSTR.NULL_BSS_F Indcates that Adjusted Cost is not accurate due to missing cost on atleast one sublot Source:NULL_F Y = YES ? At least one of the associated average cost records is missing average cost N = NO ? None of the associated average cost records are missing average cost | F11: Flag | G11: VARCHAR2(1) | H11: NULL | J11: 36
A12: Open Tax Lots Fact | B12: OPN_TAX_LOTS_FACT | C12: Arrangement Dimension Id | D12: AR_DIM_ID | E12: Arrangement Id for the account MAXIT Source: TAX_LOT_DTL_OPN/CLS.AR_ID RJT Source:TAX_LOT_OPN_MSTR.AR_ID Lookup on AR_DIM using EFF_DT | F12: NINI | G12: NUMBER(38,0) | H12: NOT NULL | J12: 7
A13: Open Tax Lots Fact | B13: OPN_TAX_LOTS_FACT | C13: Arrangement Id | D13: AR_ID | E13: Arrangement Id for the account MAXIT Source:TAX_LOT_DTL_OPN/CLS.AR_ID RJT Source:TAX_LOT_OPN_MSTR.AR_ID | F13: NINI | G13: NUMBER(9,0) | H13: NULL | J13: 3
A14: Open Tax Lots Fact | B14: OPN_TAX_LOTS_FACT | C14: Average Adjusted Cost per Unit | D14: AVG_ADJ_COST_PER_UNIT | E14: Calculated. See SRD | F14: a | G14: NUMBER(22,6) | H14: NULL | J14: 79
A15: Open Tax Lots Fact | B15: OPN_TAX_LOTS_FACT | C15: Buy Trade Number | D15: BUY_TRD_NUM | E15: Trade number for the buy when lot was established with a buy transaction MAXIT Source: TAXLOT_DTL_OPN.BUY_TRD_NUM RJT Source: TAX_LOT_OPN_MSTR.TRD_NUM | G15: VARCHAR2(80) | H15: NULL | J15: 22
A16: Open Tax Lots Fact | B16: OPN_TAX_LOTS_FACT | C16: CCAL Product Id | D16: CCAL_PD_ID | E16: Product Id assigned by CCAL MAXIT Source: TAX_LOT_DTL_OPN/CLS.PD_ID RJT Source: TAX_LOT_OPN_MSTR.CCAL_PD_ID | F16: NINI | G16: NUMBER(9,0) | H16: NULL | J16: 5
A17: Open Tax Lots Fact | B17: OPN_TAX_LOTS_FACT | C17: Certificate Number | D17: CTF_NUM | E17: MAXIT Source:TAXLOT_DTL_OPN.CTF_NUM RJT Source: TAX_LOT_OPN_MSTR.TAX_LOT_CTF_NUM | F17: Code | G17: VARCHAR2(40) | H17: NULL | J17: 24
A18: Open Tax Lots Fact | B18: OPN_TAX_LOTS_FACT | C18: Certificate Number Prefix | D18: CTF_NUM_PFX | E18: MAXIT Source:TAXLOT_DTL_OPN.CTF_NUM_PFX RJT Source: TAX_LOT_OPN_MSTR.TAX_LOT_CTF_NUM_PFX | F18: Code | G18: VARCHAR2(40) | H18: NULL | J18: 25
A19: Open Tax Lots Fact | B19: OPN_TAX_LOTS_FACT | C19: CIRD Product Id | D19: CIRD_PD_ID | E19: MAXIT Source: TAX_LOT_DTL_OPN/CLS.PD_ID RJT Source: TAX_LOT_OPN_MSTR.CCAL_PD_ID Lookup on IMT_PD_DIM using CL_PD_ID PD_ID from CIRD - can be used as join key if date context is supplied at query time | F19: NINI | G19: NUMBER(9,0) | H19: NULL | J19: 4
A20: Open Tax Lots Fact | B20: OPN_TAX_LOTS_FACT | C20: Cost Amount | D20: COST_AMT | E20: Original total purchase cost of the instrument Buy, the net amount is shown. Sell, cost sold for a sell is displayed. Note: This field cannot be used currently as it is not prorated or adjusted for changes/actions/partial sells where a change in quantity is made. MAXIT Source: TAXLOT_DTL_OPN.ORIG_COST RJT Source:TAX_LOT_OPN_ASOF.NML_ASOF_CRN_COST_AMT | F20: a | G20: NUMBER(22,6) | H20: NULL | J20: 39
A21: Open Tax Lots Fact | B21: OPN_TAX_LOTS_FACT | C21: Cost Basis Legislation Coverage Code | D21: COST_BSS_LEGS_CVR_CD | E21: Cost Basis Legislation Coverage: ?covered? securities are those impacted by the cost basis legislation (which is dependent on the security type and acquisition date) and subject to the new IRS reporting requirements. U = Uncovered Tax Lot C = Covered Tax Lot MAXIT Source: TAXLOT_DTL_OPN.CVRD_UNCVRD RJT Source: TAX_LOT_OPN_MSTR.CVRD_F | F21: Flag | G21: VARCHAR2(1) | H21: NULL | J21: 26
A22: Open Tax Lots Fact | B22: OPN_TAX_LOTS_FACT | C22: Cost Basis Legislation Coverage Flag | D22: COST_BSS_LEGS_CVR_F | E22: For Brokerage if the covered uncovered from tax lot detail open table is C, then set to Y Otherwise, set to N For RJ Trust accounts if the Covered Flag from the tax lot open master table is C, then set to Y Otherwise, set to N | F22: Flag | G22: VARCHAR2(1) | H22: NULL | J22: 75
A23: Open Tax Lots Fact | B23: OPN_TAX_LOTS_FACT | C23: Cost Basis Shareholder Provided Code | D23: COST_BSS_SHRHLR_PVDD_CD | E23: Cost Basis provided by the client. Y=Yes, N= No other code values 0 (zero) and Null. We do not have documentation on these codes MAXIT Source:TAXLOT_DTL_OPN.BSS_SHP RJT Source: None | F23: Flag | G23: VARCHAR2(1) | H23: NULL | J23: 21
A24: Open Tax Lots Fact | B24: OPN_TAX_LOTS_FACT | C24: Create Datetime | D24: CRT_DTM | F24: Date | G24: TIMESTAMP(6) | H24: NULL | J24: 69
A25: Open Tax Lots Fact | B25: OPN_TAX_LOTS_FACT | C25: Create User Name | D25: CRT_USR_NM | E25: The name that represents the user who created an occurrence of a/an Open Tax Lots Fact. | F25: Create User Name | G25: VARCHAR2(255) | H25: NOT NULL | J25: 70
A26: Open Tax Lots Fact | B26: OPN_TAX_LOTS_FACT | C26: Currency Code | D26: CCY_CD | E26: MAXIT Source: TAXLOT_DTL_OPN.CCY_CODE RJT Source: TAX_LOT_OPN_ASOF.NML_ISO_CCY_CODE | G26: VARCHAR2(7) | H26: NULL | J26: 23
A27: Open Tax Lots Fact | B27: OPN_TAX_LOTS_FACT | C27: Disallowed Wash sale Amount | D27: DISALWD_WASH_SALE_AMT | E27: MAXIT Source: TAXLOT_DTL_OPN.DISALWD_WASHSALE_AMT RJT Source: TAX_LOT_OPN_MSTR.NML_CCY_WASH_SALE_AMT | F27: a | G27: NUMBER(22,6) | H27: NULL | J27: 27
A28: Open Tax Lots Fact | B28: OPN_TAX_LOTS_FACT | C28: Dual Basis Flag | D28: DUAL_BSS_F | E28: Possible values Y = Record is a depreciated dual basis gift N = Record is not a depreciated dual basis gift For Brokerage accounts If the ACAT type is null and the Original Transaction Type is GFT from tax lot detail open And Fair market value from tax lot detail open is greater than zero And Adjusted cost amount from tax lot detail open is greater than zero And Fair market value is less than or equal to adjusted cost amount then Set to Y or If the ACAT Type is GFT or ITG from tax lot detail open and Fair market value from tax lot detail open is greater than zero And Adjusted cost amount from tax lot detail open is greater than zero And Fair market value is less than or equal to adjusted cost amount then Set to Y Otherwise, set to N For RJ Trust accounts If the Tax Lot Transaction Type Identifier is 2851 from the tax lot open master table and the SBC As Of Fair Market Value from the tax lot open as of table is greater than zero and the SBC As Of Adjusted Cost Amount from the tax lot open as of table is greater than zero and the SBC As Of Fair Market Value is less than or equal to the SBC As Of Adjusted Cost Amount then Set to Y Otherwise, set to N | F28: Flag | G28: VARCHAR2(1) | H28: NULL | J28: 76
A29: Open Tax Lots Fact | B29: OPN_TAX_LOTS_FACT | C29: Effective Date | D29: EFf_DT | E29: MAXIT Source: TAXLOT_DTL_OPN.EFF_DT_x000D_ RJT Source: TAX_LOT_OPN_ASOF.EFF_FM_DT_x000D_ _x000D_ | F29: Effective Date | G29: DATE | H29: NOT NULL | J29: 14
A30: Open Tax Lots Fact | B30: OPN_TAX_LOTS_FACT | C30: Effective Date Dimension Id | D30: EFF_DT_DIM_ID | E30: Synthetic Key identifying a single date in the DATE Dimension | F30: NINI | G30: NUMBER(38,0) | H30: NOT NULL | J30: 78
A31: Open Tax Lots Fact | B31: OPN_TAX_LOTS_FACT | C31: End Date | D31: END_DT | E31: MAXIT Source: TAXLOT_DTL_OPN.END_DT RJT Source: TAX_LOT_OPN_ASOF.EFF_TO_DT | G31: DATE | H31: NULL | J31: 13
A32: Open Tax Lots Fact | B32: OPN_TAX_LOTS_FACT | C32: End Date Dimension Id | D32: END_DT_DIM_ID | E32: Synthetic Key identifying a single date in the DATE Dimension | F32: NINI | G32: NUMBER(38,0) | H32: NOT NULL | J32: 81
A33: Open Tax Lots Fact | B33: OPN_TAX_LOTS_FACT | C33: Exchange Rate | D33: EXG_RATE | E33: MAXIT Source: TAXLOT_DTL_OPN.EXG_RATE RJT Source: TAX_LOT_OPN_ASOF.SBC_EXG_RATE | F33: a | G33: NUMBER(22,6) | H33: NULL | J33: 28
A34: Open Tax Lots Fact | B34: OPN_TAX_LOTS_FACT | C34: Fair Market Value Of Gift Or Inheritance | D34: FAIR_MKT_VAL_OF_GIFT_OR_INHTN | E34: MAXIT Source: TAXLOT_DTL_OPN.FMV RJT SOurce: TAX_LOT_OPN_ASOF.NML_CCY_ASOF_FAIR_MKT_VAL_AMT For MAXIT (Brokerage) Fair market value of the tax lot at the point of gifting or inheritance Source: FMV For gifted or inherited transactions only. Sourced from: 1) account to account RAD Activity receive record sent to Maxit from RJ 2) CBRS record received from contra firm 3) manual entry by business | F34: a | G34: NUMBER(22,6) | H34: NULL | J34: 29
A35: Open Tax Lots Fact | B35: OPN_TAX_LOTS_FACT | C35: Gift Date | D35: GIFT_DT | E35: MAXIT Source: TAXLOT_DTL_OPN.GIFT_DT RJT Source: TAX_LOT_OPN_MSTR.GIFT_DT For gifted tax lots this gives date of gift. Source: GIFT_DT | G35: DATE | H35: NULL | J35: 30
A36: Open Tax Lots Fact | B36: OPN_TAX_LOTS_FACT | C36: Gift Date Dimension Id | D36: GIFT_DT_DIM_ID | E36: Synthetic Key identifying a single date in the DATE Dimension | F36: NINI | G36: NUMBER(38,0) | H36: NOT NULL | J36: 82
A37: Open Tax Lots Fact | B37: OPN_TAX_LOTS_FACT | C37: Investment Product Dimension Id | D37: IMT_PD_DIM_ID | E37: MAXIT Source: TAX_LOT_DTL_OPN/CLS.PD_ID RJT Source: TAX_LOT_OPN_MSTR.CCAL_PD_ID Lookup on IMT_PD_DIM using CL_PD_ID | F37: NINI | G37: NUMBER(38,0) | H37: NOT NULL | J37: 6
A38: Open Tax Lots Fact | B38: OPN_TAX_LOTS_FACT | C38: Last Update Datetime | D38: LAST_UDT_DTM | G38: TIMESTAMP(6) | H38: NULL | J38: 71
A39: Open Tax Lots Fact | B39: OPN_TAX_LOTS_FACT | C39: Last Update User Name | D39: LAST_UDT_USR_NM | E39: The name that represents the user or application who inserted, updated, or deleted each occurrence of Open Tax Lots Fact. | F39: Last Update User Name | G39: VARCHAR2(255) | H39: NOT NULL | J39: 72
A40: Open Tax Lots Fact | B40: OPN_TAX_LOTS_FACT | C40: Life to Date Market Discount | D40: LIFE_TO_DTD_MKT_DCN | E40: Life to date market discount amount_x000D_ _x000D_ Total market discount accrued since the purchase of the bond_x000D_ _x000D_ MAXIT Source: TAXLOT_DTL_OPN.LTD_MKT_DISCOUNT | F40: a | G40: NUMBER(22,6) | H40: NULL | I40: Frozen | J40: 34
...

Sheet Table
A1: COLUMN_NAME | B1: DATA_TYPE | C1: NULLABLE | D1: DATA_DEFAULT | E1: COLUMN_ID | F1: COMMENTS
A2: ACAT_TP | B2: VARCHAR2(500 BYTE) | C2: Yes | E2: 17 | F2: MAXIT Source: = TAXLOT_DTL_OPN.ACATTYPE RJT Source: None Type of Transfer indicated by the external source when transferred using ACAT Values GFT = Gift INH = Inherited ITG = Inherited Than Gifted NTT = NonTaxable to Taxable DRIP = A Direct Registration System (DRS)/Direct Reinvestment Plan NULL = none various other values are available as well
A3: ACAT_TP_CD | B3: VARCHAR2(40 BYTE) | C3: Yes | E3: 18 | F3: MAXIT Source: = TAXLOT_DTL_OPN.ACATTYPE RJT Source: None Type of Transfer Code indicated by the external source when transferred using ACAT Values GFT = Gift INH = Inherited ITG = Inherited Than Gifted NTT = NonTaxable to Taxable DRIP = A Direct Registration System (DRS)/Direct Reinvestment Plan NULL = none various other values are available as well
A4: ACG_TP_CD | B4: VARCHAR2(1 BYTE) | C4: Yes | E4: 8 | F4: MAXIT Source: TAXLOT_DTL_OPN.AC_TP RJT Source: TAX_LOT_OPN_MSTR.ACG_TP_CODE Accounting type code from SIS (e.g., 1,2,6). 1= Cash Account 2= Margin Account 3= Special lot 2019 5= Special lot 2013 6= Short margin Account
A5: ACG_TP_DIM_ID | B5: NUMBER(38,0) | C5: No | E5: 15 | F5: MAXIT Source: TAXLOT_DTL_OPN.AC_TP RJT Source: TAX_LOT_OPN_MSTR.ACG_TP_CODE Lookup on Accounting Type Dimension
A6: ACG_TP_ID | B6: NUMBER(38,0) | C6: Yes | E6: 70 | F6: Numeric identifier of the accounting type ID (e.g., 1006, 1001) Lookup using Accounting type Code (MAXIT TAXLOT_DTL_OPN.AC_TP, RJT TAX_LOT_OPN_MSTR.ACG_TP_CODE)
A7: ACG_TP_NM | B7: VARCHAR2(500 BYTE) | C7: Yes | E7: 16 | F7: MAXIT Source: TAXLOT_DTL_OPN.AC_TP RJT Source: TAX_LOT_OPN_MSTR.ACG_TP_CODE Lookup on Accounting Type Dimension Accounting type name (e.g., cash account,margin account)
A8: ACQ_DT | B8: DATE | C8: Yes | E8: 19 | F8: Date on which the lot was acquired MAXIT source: TAXLOT_DTL_OPN.ACQ_DT RJT Source:TAX_LOT_OPN_MSTR.TD
A9: ACQ_DT_DIM_ID | B9: NUMBER(38,0) | C9: No | E9: 75 | F9: Synthetic Key identifying a single date in the DATE Dimension
A10: ADJ_COST | B10: NUMBER(22,6) | C10: Yes | E10: 20 | F10: Adjusted cost for the Lot MAXIT source: TAXLOT_DTL_OPN.ADJ_COST RJT Source: TAX_LOT_OPN_ASOF NML_CCY_ASOF_ADJ_COST_AMT
A11: ADJ_COST_NOT_ACRT_F | B11: VARCHAR2(1 BYTE) | C11: Yes | E11: 36 | F11: MAXIT Source: TAXLOT_DTL_OPN.NULL_F RJT Source: TAX_LOT_OPN_MSTR.NULL_BSS_F Indcates that Adjusted Cost is not accurate due to missing cost on atleast one sublot Source:NULL_F Y = YES – At least one of the associated average cost records is missing average cost N = NO – None of the associated average cost records are missing average cost
A12: AR_DIM_ID | B12: NUMBER(38,0) | C12: No | E12: 7 | F12: Arrangement Id for the account MAXIT Source: TAX_LOT_DTL_OPN/CLS.AR_ID RJT Source:TAX_LOT_OPN_MSTR.AR_ID Lookup on AR_DIM using EFF_DT
A13: AR_ID | B13: NUMBER | C13: Yes | E13: 3 | F13: Arrangement Id for the account MAXIT Source:TAX_LOT_DTL_OPN/CLS.AR_ID RJT Source:TAX_LOT_OPN_MSTR.AR_ID
... A21: COST_BSS_SHRHLR_PVDD_CD | B21: VARCHAR2(1 BYTE) | C21: Yes | E21: 21 | F21: Cost Basis provided by the client. Y=Yes, N= No other code values 0 (zero) and Null. We do not have documentation on these codes MAXIT Source:TAXLOT_DTL_OPN.BSS_SHP RJT Source: None
A22: CRT_DTM | B22: TIMESTAMP(6) | C22: No | D22: SYSDATE | E22: 65
A23: CRT_USR_NM | B23: VARCHAR2(256 BYTE) | C23: No | D23: USER | E23: 66 | F23: The name that represents the user who created an occurrence of a/an Position Open Tax Lots Fact.
A24: CTF_NUM | B24: VARCHAR2(40 BYTE) | C24: Yes | E24: 24 | F24: MAXIT Source:TAXLOT_DTL_OPN.CTF_NUM RJT Source: TAX_LOT_OPN_MSTR.TAX_LOT_CTF_NUM
A25: CTF_NUM_PFX | B25: VARCHAR2(40 BYTE) | C25: Yes | E25: 25 | F25: MAXIT Source:TAXLOT_DTL_OPN.CTF_NUM_PFX RJT Source: TAX_LOT_OPN_MSTR.TAX_LOT_CTF_NUM_PFX
A26: DISALWD_WASH_SALE_AMT | B26: NUMBER(22,6) | C26: Yes | E26: 27 | F26: MAXIT Source: TAXLOT_DTL_OPN.DISALWD_WASHSALE_AMT RJT Source: TAX_LOT_OPN_MSTR.NML_CCY_WASH_SALE_AMT
A27: DUAL_BSS_F | B27: VARCHAR2(1 BYTE) | C27: Yes | E27: 83 | F27: Possible values Y = Record is a depreciated dual basis gift N = Record is not a depreciated dual basis gift For Brokerage accounts If the ACAT type is null and the Original Transaction Type is GFT from tax lot detail open And Fair market value from tax lot detail open is greater than zero And Adjusted cost amount from tax lot detail open is greater than zero And Fair market value is less than or equal to adjusted cost amount then Set to Y or If the ACAT Type is GFT or ITG from tax lot detail open and Fair market value from tax lot detail open is greater than zero And Adjusted cost amount from tax lot detail open is greater than zero And Fair market value is less than or equal to adjusted cost amount then Set to Y Otherwise, set to N For RJ Trust accounts If the Tax Lot Transaction Type Identifier is 2851 from the tax lot open master table and the SBC As Of Fair Market Value from the tax lot open as of table is greater than zero and the SBC As Of Adjusted Cost Amount from the tax lot open as of table is greater than zero and the SBC As Of Fair Market Value is less than or equal to the SBC As Of Adjusted Cost Amount then Set to Y Otherwise, set to N
A28: EFF_DT | B28: DATE | C28: Yes | E28: 14 | F28: MAXIT Source: TAXLOT_DTL_OPN.EFF_DT RJT Source: TAX_LOT_OPN_ASOF.EFF_FM_DT
A29: EFF_DT_DIM_ID | B29: NUMBER(38,0) | C29: No | E29: 73 | F29: Synthetic Key identifying a single date in the DATE Dimension
A30: END_DT | B30: DATE | C30: No | E30: 13 | F30: MAXIT Source: TAXLOT_DTL_OPN.END_DT RJT Source: TAX_LOT_OPN_ASOF.EFF_TO_DT
A31: END_DT_DIM_ID | B31: NUMBER(38,0) | C31: No | E31: 74 | F31: Synthetic Key identifying a single date in the DATE Dimension
A32: EXG_RATE | B32: NUMBER(22,6) | C32: Yes | E32: 28 | F32: MAXIT Source: TAXLOT_DTL_OPN.EXG_RATE RJT Source: TAX_LOT_OPN_ASOF.SBC_EXG_RATE
A33: FAIR_MKT_VAL_OF_GIFT_OR_INHTN | B33: NUMBER(22,6) | C33: Yes | E33: 29 | F33: MAXIT Source: TAXLOT_DTL_OPN.FMV RJT SOurce: TAX_LOT_OPN_ASOF.NML_CCY_ASOF_FAIR_MKT_VAL_AMT For MAXIT (Brokerage) Fair market value of the tax lot at the point of gifting or inheritance Source: FMV For gifted or inherited transactions only. Sourced from: 1) account to account RAD Activity receive record sent to Maxit from RJ 2) CBRS record received from contra firm 3) manual entry by business
A34: GIFT_DT | B34: DATE | C34: Yes | E34: 30 | F34: MAXIT Source: TAXLOT_DTL_OPN.GIFT_DT RJT Source: TAX_LOT_OPN_MSTR.GIFT_DT For gifted tax lots this gives date of gift. Source: GIFT_DT
A35: GIFT_DT_DIM_ID | B35: NUMBER(38,0) | C35: No | E35: 76 | F35: Synthetic Key identifying a single date in the DATE Dimension
A36: IMT_PD_DIM_ID | B36: NUMBER(38,0) | C36: No | E36: 6 | F36: Surrogate key for Instrument Product Dim
A37: LAST_UDT_DTM | B37: TIMESTAMP(6) | C37: No | D37: SYSDATE | E37: 71
A38: LAST_UDT_USR_NM | B38: VARCHAR2(256 BYTE) | C38: No | D38: USER | E38: 72 | F38: The name that represents the user or application who inserted, updated, or deleted each occurrence of Position Open Tax Lots Fact.
A39: LIFE_TO_DTD_MKT_DCN | B39: NUMBER(22,6) | C39: Yes | E39: 34 | F39: Life to date market discount amount Total market discount accrued since the purchase of the bond MAXIT Source: TAXLOT_DTL_OPN.LTD_MKT_DISCOUNT
A40: LONG_SHRT_POS_CD | B40: VARCHAR2(1 BYTE) | C40: Yes | E40: 32 | F40: A value that represents the tax lot being a long or short position. Valid Values: L = Long S = Short MAXIT Source: TAXLOT_DTL_OPN.LONG_SHRT_POS rjt sOURCE: TAX_LOT_OPN_MSTR.POS_LONG_SHRT_CODE
A41: LOSS_NOT_ALWD_F | B41: VARCHAR2(1 BYTE) | C41: Yes | E41: 33 | F41: MAXIT Source: TAXLOT_DTL_OPN.LOSS_NOT_ALLOWED RJT Source: None In a cash and stock merger the client may not be allowed to take a loss on the disposition of the old stock, any losses are rolled into the new stock. Merger / Acquisition or Corporate Inversion Transactions. This field is currently used on Closed Tax Lot Tax Reporting at this time. Values: N = No, Loss allowed Y = Yes, No Loss allowed
A42: MISS_COST_BSS_F | B42: VARCHAR2(1 BYTE) | C42: Yes | E42: 35 | F42: Indicates that Cost basis is not available for this position MAXIT Source: TAXLOT_DTL_OPN.MISS_COST_F RJT Source: TAX_LOT_OPN_MSTR.MISS_COST_F
A43: MISS_IVS_COST_F | B43: VARCHAR2(1 BYTE) | C43: Yes | E43: 84 | F43: For Brokerage accounts If the reinvest flag from tax lot detail open is not equal to Y If the missing cost flag from tax lot detail open is Y, then set to Y If the missing average cost flag (null flag) from tax lot detail open is Y, then set to Y Otherwise, set to N For RJ Trust accounts If the reinvest flag from tax lot open master is not equal to Y If the Missing Cost Flag from the tax lot open master table is Y, then set to Y If the Null Basis Flag from the tax lot open master table is Y, then set to Y Otherwise, set to N
A44: OPN_PRC_FCTR | B44: NUMBER(22,6) | C44: Yes | E44: 37 | F44: Price_factor of opening transaction Used for factored bonds MAXIT Source: TAXLOT_DTL_OPN.OPN_FCTR RJT Source: TAX_LOT_OPN_MSTR.NML_CCY_OPN_PRC_FCTR
A45: OPN_TAX_LOTS_FACT_ID | B45: NUMBER(38,0) | C45: No | E45: 1
A46: OPN_TXN_EV_TP | B46: VARCHAR2(40 BYTE) | C46: Yes | E46: 38 | F46: Source: TAXLOT_DTL_OPN.OPN_TXN_EV_ID RJT Source: TAX_LOT_OPN_MSTR.TAX_LOT_TXN_EV_TP_ID For open lots – Maxit Event ID For closed lots – Maxit Event ID of the closing transaction For open and closed lots, this field includes the 'event' of the opening transaction This is a Maxit created Event Name to identify tax lots and create associations between tax lots"
A47: ORIG_EV_TP | B47: VARCHAR2(32 BYTE) | C47: Yes | E47: 40 | F47: MAAXIT Source: ORIG_EV_ID Opening transaction original event ID. Used when opening transaction event ID represents a corporate action, in which case the original event ID (such as DRIP BUY, gift, or inheritance, etc. is more important) Maxit ID of the original opening transaction (i.e. would be the id associated with a buy should a reorg/corp action come along and close out that open and create new open with new opening transaction id). Source: ORIG_EV_ID
...
